Workbook
Name HEADOFTHEFAM: 'HEAD OF THE FAMILY'!$B$5:$P$805
Name CHILDREN: CHILDREN!$A$5:$I$1851

Sheet HEAD OF THE FAMILY
A1: BARANGAY SAN MIGUEL II DATA GATHERING FOR THE HEAD OF THE FAMILY
A4: COUNT | B4: HEAD OF THE FAMILY / FULL NAME | C4: BRGY. OFFICIALS / SENIOR / 4PS / SOLO PARENT / PWD / KDBM / THIRD GEN. | D4: MM/DD/YYYY | E4: VOTER REGISTER | G4: PH - PAMASONG HANDOG / R - RICE | H4: PARTNER / FULLNAME | I4: BRGY. OFFICIALS / SENIOR / 4PS / SOLO PARENT / PWD / KDBM / THIRD GEN. | J4: ADDRESS | L4: MM/DD/YYYY | M4: VOTER REGISTER | O4: QUANTITY | P4: NOTICE!
A5: NO. | B5: FIRST NAME / MI. / LAST NAME | C5: CATEGORY | D5: BIRTHDAY | E5: PRECINT NO. | F5: STATUS | G5: PH OR R | H5: FIRST NAME / MI. / LAST NAME | I5: CATEGORY | J5: BLK | K5: LOT | L5: BIRTHDAY | M5: PRECINT NO. | N5: STATUS | O5: PH OR R | P5: REMARKS
A6: =IF(B6="","",ROW()-5) -> 1 | B6: AARON CARL EJANDRA | C6: N/A | F6: ACTIVE | G6: R | H6: MA. LOUELLA L. EJANDRA | J6: BLK 3 | K6: 5 | N6: UNREGISTERED
A7: 2 | B7: ABEL CARIAS | C7: N/A | F7: UNREGISTERED | G7: R | H7: RACHELLE JOYA CARIAS | J7: BLK 5 | K7: 35 | N7: ACTIVE
A8: =IF(B8="","",ROW()-5) -> 3 | B8: ACE ANGELO A. SANTOS | C8: N/A | F8: ACTIVE | G8: R | H8: LEA TAGUM | J8: BLK 41 | K8: 24 | N8: UNREGISTERED
A9: =IF(B9="","",ROW()-5) -> 4 | B9: ADELAIDA O. PULGA | C9: SENIOR | F9: ACTIVE | G9: PH | J9: BLOCK 4 | K9: 37
A10: =IF(B10="","",ROW()-5) -> 5 | B10: ADORACION LLENO | C10: SENIOR | F10: ACTIVE | G10: PH | J10: BLK 46 | K10: 13
A11: =IF(B11="","",ROW()-5) -> 6 | B11: ADRIAN SIRAY SR. | C11: N/A | F11: ACTIVE | G11: PH | H11: MA. TERESA REYES | I11: 4PS | J11: BLOCK 4 | K11: 8 | N11: ACTIVE
A12: =IF(B12="","",ROW()-5) -> 7 | B12: AERON DE GORO | C12: N/A | F12: UNREGISTERED | G12: R | H12: VADILEE MAGNO | J12: BLK 5 | K12: 4 | N12: ACTIVE
A13: =IF(B13="","",ROW()-5) -> 8 | B13: AGAPITO A. HILARIO | C13: SENIOR | E13: 0867B | F13: ACTIVE | G13: PH | H13: EVANGELINA S. HILARIO | I13: SENIOR | J13: BLK 1 | K13: 4 | M13: 0867B | N13: ACTIVE
A14: =IF(B14="","",ROW()-5) -> 9 | B14: AGOSTO ESTILLANA | C14: SENIOR | F14: UNREGISTERED | G14: R | H14: ROSITA ESTILLANA | J14: BLK 41 | K14: 25 | N14: ACTIVE
A15: =IF(B15="","",ROW()-5) -> 10 | B15: AILEEN S. VILLARINO | C15: N/A | F15: ACTIVE | G15: R | J15: BLOCK 4 | K15: 12
A16: =IF(B16="","",ROW()-5) -> 11 | B16: AIRA VILLARINO | C16: N/A | F16: ACTIVE | G16: R | J16: BLOCK 4 | K16: 6
A17: =IF(B17="","",ROW()-5) -> 12 | B17: AL DESPABELADERAS | C17: N/A | F17: ACTIVE | G17: R | H17: SUSANA DESPABELADERAS | J17: BLK 46 | K17: 2 | N17: ACTIVE
A18: =IF(B18="","",ROW()-5) -> 13 | B18: ALBERT ARCILLA | C18: N/A | F18: ACTIVE | G18: PH | H18: AILEEN ARCILLA | J18: BLK 5 | K18: 39 | N18: ACTIVE
A19: =IF(B19="","",ROW()-5) -> 14 | B19: ALBERT MANANGAT | C19: N/A | F19: ACTIVE | G19: R | H19: NORALIN MERIN | J19: BLK 41 | K19: 5 | N19: UNREGISTERED
A20: =IF(B20="","",ROW()-5) -> 15 | B20: ALBERT SANTOS | C20: N/A | F20: ACTIVE | G20: R | H20: MARY ANNE BALADAD | J20: BLK 45 | K20: 19 | N20: ACTIVE
A21: =IF(B21="","",ROW()-5) -> 16 | B21: ALBERTO A MACABENTA | C21: SENIOR | F21: ACTIVE | G21: PH | H21: DISCORA T MACABENTA | I21: PWD | J21: BLK 45 | K21: 10 | N21: ACTIVE
A22: =IF(B22="","",ROW()-5) -> 17 | B22: ALBERTO E DE GUZMAN | C22: SENIOR | F22: ACTIVE | G22: PH | H22: ALICE DE GUZMAN | J22: BLK 46 | K22: 36
A23: =IF(B23="","",ROW()-5) -> 18 | B23: ALBERTO LOBRIO JR. | C23: THIRD GEN | F23: ACTIVE | G23: PH | H23: LETECIA LOBRIO | I23: KDBM | J23: BLK 49 | K23: 27 | N23: ACTIVE
A24: =IF(B24="","",ROW()-5) -> 19 | B24: ALBERTO LOBRIO SR. | C24: SENIOR | F24: ACTIVE | G24: PH | H24: CECILA LOBRIO | I24: SENIOR | J24: BLK 49 | K24: 27 | N24: ACTIVE
A25: =IF(B25="","",ROW()-5) -> 20 | B25: ALBERTO MANUEL | C25: SENIOR | F25: ACTIVE | G25: PH | H25: LETECIA AMORIN | J25: BLK 46 | K25: 21 | N25: ACTIVE
A26: =IF(B26="","",ROW()-5) -> 21 | B26: ALBERTO R. CAMPOS | C26: N/A | F26: ACTIVE | G26: PH | H26: MARY JOY A CAMPOS | I26: BRGY. OFFICIALS | J26: BLK 3 | K26: 17 | N26: ACTIVE
A27: =IF(B27="","",ROW()-5) -> 22 | B27: ALEJANDRO G GALLARDO JR. | C27: N/A | F27: ACTIVE | G27: PH | H27: LUZVIMINDA L GALLARDO | I27: 4PS | J27: BLK 46 | K27: 9A | N27: ACTIVE
A28: =IF(B28="","",ROW()-5) -> 23 | B28: ALEX CHENG | C28: THIRD GEN | F28: INACTIVE | G28: N/A | H28: ROSEMARIE LLANERA | J28: BLOCK 4 | K28: 37 | N28: UNREGISTERED
A29: =IF(B29="","",ROW()-5) -> 24 | B29: ALEXANDER ALONZO | C29: SENIOR | F29: ACTIVE | G29: PH | J29: BLK 1
A30: =IF(B30="","",ROW()-5) -> 25 | B30: ALEXANDER CAMPAÑA | C30: SENIOR | F30: ACTIVE | G30: PH | H30: MAGDALENA D. CAMPAÑA | J30: BLK 1 | K30: 29 | N30: UNREGISTERED
A31: =IF(B31="","",ROW()-5) -> 26 | B31: ALFRED IVAN EJANDRA | C31: N/A | F31: ACTIVE | G31: R | H31: LEANDRA L. EJANDRA | J31: BLK 3 | K31: 5 | N31: UNREGISTERED
A32: =IF(B32="","",ROW()-5) -> 27 | B32: ALICIA D. REYES | C32: SENIOR | F32: ACTIVE | G32: PH | J32: BLOCK 4 | K32: 8
A33: =IF(B33="","",ROW()-5) -> 28 | B33: ALICIA R. MAGBANUA | C33: SENIOR | F33: INACTIVE | G33: N/A | J33: BLK 45 | K33: 26
A34: =IF(B34="","",ROW()-5) -> 29 | B34: ALLAN DAVE D. EVANGELISTA | C34: N/A | F34: ACTIVE | G34: R | H34: SHIA URDINADO | J34: BLOCK 4 | K34: 6 | N34: UNREGISTERED
A35: =IF(B35="","",ROW()-5) -> 30 | B35: ALLAN MAGNO | C35: BRGY. OFFICIALS | F35: ACTIVE | G35: PH | J35: BLK 5 | O35: FOR CHECKING
A36: =IF(B36="","",ROW()-5) -> 31 | B36: ALLAN N. HIPOLITO JR. | C36: N/A | F36: ACTIVE | G36: R | H36: ALEXIS C. RONDILLA | J36: BLK 49 | K36: 3 | N36: UNREGISTERED
A37: =IF(B37="","",ROW()-5) -> 32 | B37: ALLAN P. HIPOLITO SR. | C37: 4PS | F37: ACTIVE | G37: PH | H37: ELSIE HIPOLITO | I37: BRGY. OFFICIALS | J37: BLK 49 | K37: 2 | N37: ACTIVE
A38: =IF(B38="","",ROW()-5) -> 33 | B38: ALLAN S. PUSING | C38: SOLO PARENT | F38: ACTIVE | G38: PH | J38: BLK 45 | K38: 31
A39: =IF(B39="","",ROW()-5) -> 34 | B39: ALLEN EDWARD T. MONCES | C39: N/A | F39: UNREGISTERED | G39: R | H39: PRECY MAE L. BULO | J39: BLK 49 | K39: 3 | N39: ACTIVE
A40: =IF(B40="","",ROW()-5) -> 35 | B40: ALVIN BAREZA | C40: N/A | F40: UNREGISTERED | G40: R | H40: ELAINE ROSE RONASE | J40: BLK 49 | K40: 27 | N40: ACTIVE
A41: =IF(B41="","",ROW()-5) -> 36 | B41: AMBROSO ALZAGA | C41: SENIOR | F41: ACTIVE | G41: PH | H41: PIEDAD ALZAGA | I41: SENIOR | J41: BLK 1 | K41: 12
A42: =IF(B42="","",ROW()-5) -> 37 | B42: AMPARO L. MARCOS | C42: SENIOR | F42: ACTIVE | G42: PH | J42: BLK 45 | K42: 28-B
...

Sheet CHILDREN
A1: BARANGAY SAN MIGUEL II DATA GATHERING FOR THE CHILDREN
A4: COUNT | B4: FULL NAME | E4: FULL NAME | F4: BRGY. OFFICIALS / 4PS / SOLO PARENT / PWD / KDBM / THIRD GEN. | G4: MM/DD/YYYY | H4: VOTER REGISTRATION | J4: FOR CHECKING | K4: BLK
A5: NO. | B5: SURNAME | C5: FIRSTNAME | D5: MI | E5: HEAD OF THE FAMILY | F5: CATEGORY | G5: BIRTHDAY | H5: PRECINT NO. | I5: STATUS | J5: REMARKS
A6: =IF(B6="","",ROW()-5) -> 1 | B6: BILLONES | C6: NELJOHN | E6: NELVIN BILLONES | K6: =VLOOKUP(E6,'HEAD OF THE FAMILY'!$B$6:$J1851,9,FALSE) -> BLK 1
A7: =IF(B7="","",ROW()-5) -> 2 | B7: BILLONES | C7: PRECIUS YHANA | E7: NELVIN BILLONES | K7: =VLOOKUP(E7,'HEAD OF THE FAMILY'!$B$6:$J1851,9,FALSE) -> BLK 1
A8: =IF(B8="","",ROW()-5) -> 3 | B8: BILLONES | C8: PRINCE YUAN | E8: NELVIN BILLONES | K8: =VLOOKUP(E8,'HEAD OF THE FAMILY'!$B$6:$J1851,9,FALSE) -> BLK 1
A9: =IF(B9="","",ROW()-5) -> 4 | B9: BILLONES | C9: NERISSA | D9: P. | E9: NELVIN BILLONES | J9: SENIOR/FOR CHECKING | K9: =VLOOKUP(E9,'HEAD OF THE FAMILY'!$B$6:$J1851,9,FALSE) -> BLK 1
A10: =IF(B10="","",ROW()-5) -> 5 | B10: BILLONES | C10: MARK GIL AERON | D10: P. | E10: ROGELIO S. BILLONES | K10: =VLOOKUP(E10,'HEAD OF THE FAMILY'!$B$6:$J1851,9,FALSE) -> BLK 1
A11: =IF(B11="","",ROW()-5) -> 6 | B11: MARTIN | C11: MARIANNE MILES | E11: NORMAN BILLONES | K11: =VLOOKUP(E11,'HEAD OF THE FAMILY'!$B$6:$J1851,9,FALSE) -> BLK 1
A12: =IF(B12="","",ROW()-5) -> 7 | B12: BILLONES | C12: JOHN VILLMAR | D12: M. | E12: NORMAN BILLONES | K12: =VLOOKUP(E12,'HEAD OF THE FAMILY'!$B$6:$J1851,9,FALSE) -> BLK 1
A13: =IF(B13="","",ROW()-5) -> 8 | B13: BILLONES | C13: SHARESCA MILES | D13: M. | E13: NORMAN BILLONES | K13: =VLOOKUP(E13,'HEAD OF THE FAMILY'!$B$6:$J1851,9,FALSE) -> BLK 1
A14: =IF(B14="","",ROW()-5) -> 9 | B14: BILLONES | C14: AYRA NAINE | D14: M. | E14: NORMAN BILLONES | K14: =VLOOKUP(E14,'HEAD OF THE FAMILY'!$B$6:$J1851,9,FALSE) -> BLK 1
A15: =IF(B15="","",ROW()-5) -> 10 | B15: BILLONES | C15: STEPHEN GAEL | D15: M. | E15: NORMAN BILLONES | K15: =VLOOKUP(E15,'HEAD OF THE FAMILY'!$B$6:$J1851,9,FALSE) -> BLK 1
A16: =IF(B16="","",ROW()-5) -> 11 | B16: BILLONES | C16: E.R | E16: NORMAN BILLONES | K16: =VLOOKUP(E16,'HEAD OF THE FAMILY'!$B$6:$J1851,9,FALSE) -> BLK 1
A17: =IF(B17="","",ROW()-5) -> 12 | B17: LABUTIN | C17: JHONROGELIO | D17: B. | E17: ROGELIO A. LABUTIN | K17: =VLOOKUP(E17,'HEAD OF THE FAMILY'!$B$6:$J1851,9,FALSE) -> BLK 1
A18: =IF(B18="","",ROW()-5) -> 13 | B18: LABUTIN | C18: ARZEL | D18: B. | E18: ROGELIO A. LABUTIN | K18: =VLOOKUP(E18,'HEAD OF THE FAMILY'!$B$6:$J1851,9,FALSE) -> BLK 1
A19: =IF(B19="","",ROW()-5) -> 14 | B19: AYUDAN | C19: MARIA PAULIN | D19: C. | E19: RENATO AYUDAN | K19: =VLOOKUP(E19,'HEAD OF THE FAMILY'!$B$6:$J1851,9,FALSE) -> BLK 1
A20: =IF(B20="","",ROW()-5) -> 15 | B20: LAOLA | C20: ELLA | D20: C. | E20: RENATO AYUDAN | K20: =VLOOKUP(E20,'HEAD OF THE FAMILY'!$B$6:$J1851,9,FALSE) -> BLK 1
A21: =IF(B21="","",ROW()-5) -> 16 | B21: SALAMAT | C21: SHAWN JAYVE | E21: SHERWIN JAY SALAMAT | K21: =VLOOKUP(E21,'HEAD OF THE FAMILY'!$B$6:$J1851,9,FALSE) -> BLK 1
A22: =IF(B22="","",ROW()-5) -> 17 | B22: SALAMAT | C22: SHAMARA JHADE | E22: SHERWIN JAY SALAMAT | K22: =VLOOKUP(E22,'HEAD OF THE FAMILY'!$B$6:$J1851,9,FALSE) -> BLK 1
A23: =IF(B23="","",ROW()-5) -> 18 | B23: MIRASOL | C23: JEFFREY S. MIRASOL | J23: FOR CHECKING | K23: =VLOOKUP(E23,'HEAD OF THE FAMILY'!$B$6:$J1851,9,FALSE) -> #N/A
A24: =IF(B24="","",ROW()-5) -> 19 | B24: BADAGUAS | C24: JASMIR ALI | D24: M. | E24: JENNALYN S. MIRASOL | K24: =VLOOKUP(E24,'HEAD OF THE FAMILY'!$B$6:$J1851,9,FALSE) -> BLK 1
A25: =IF(B25="","",ROW()-5) -> 20 | B25: LEBOSADA | C25: JANEGELLE | D25: H. | E25: AGAPITO A. HILARIO | K25: =VLOOKUP(E25,'HEAD OF THE FAMILY'!$B$6:$J1851,9,FALSE) -> BLK 1
A26: =IF(B26="","",ROW()-5) -> 21 | B26: CABRERA | C26: JAYCEERYN | D26: H. | E26: AGAPITO A. HILARIO | K26: =VLOOKUP(E26,'HEAD OF THE FAMILY'!$B$6:$J1851,9,FALSE) -> BLK 1
A27: =IF(B27="","",ROW()-5) -> 22 | B27: AMASA | C27: PRIMO KIEL | E27: PRINCE NHIMWELL L. AMASA | K27: =VLOOKUP(E27,'HEAD OF THE FAMILY'!$B$6:$J1851,9,FALSE) -> BLK 1
A28: =IF(B28="","",ROW()-5) -> 23 | B28: AMASA | C28: PRINCE NHIMWELL | D28: L. | E28: NHOEL D. AMASA | K28: =VLOOKUP(E28,'HEAD OF THE FAMILY'!$B$6:$J1851,9,FALSE) -> BLK 1
A29: =IF(B29="","",ROW()-5) -> 24 | B29: AMASA | C29: NHICOLE | D29: L. | E29: NHOEL D. AMASA | K29: =VLOOKUP(E29,'HEAD OF THE FAMILY'!$B$6:$J1851,9,FALSE) -> BLK 1
A30: =IF(B30="","",ROW()-5) -> 25 | B30: AMASA | C30: NHATALEE | D30: L. | E30: NHOEL D. AMASA | K30: =VLOOKUP(E30,'HEAD OF THE FAMILY'!$B$6:$J1851,9,FALSE) -> BLK 1
A31: =IF(B31="","",ROW()-5) -> 26 | B31: AMASA | C31: ANGELITO | D31: L. | E31: NHOEL D. AMASA | K31: =VLOOKUP(E31,'HEAD OF THE FAMILY'!$B$6:$J1851,9,FALSE) -> BLK 1
A32: =IF(B32="","",ROW()-5) -> 27 | B32: AMASA | C32: ROY | E32: NELSON D. AMASA | K32: =VLOOKUP(E32,'HEAD OF THE FAMILY'!$B$6:$J1851,9,FALSE) -> BLK 1
A33: =IF(B33="","",ROW()-5) -> 28 | B33: AMASA | C33: JOSEPH | D33: I. | E33: JOSHUA D. AMASA | K33: =VLOOKUP(E33,'HEAD OF THE FAMILY'!$B$6:$J1851,9,FALSE) -> BLK 1
A34: =IF(B34="","",ROW()-5) -> 29 | B34: BULOS | C34: DAPHNE CHLOE | E34: JENNY C. HUGO | K34: =VLOOKUP(E34,'HEAD OF THE FAMILY'!$B$6:$J1851,9,FALSE) -> BLK 1
A35: =IF(B35="","",ROW()-5) -> 30 | B35: BULOS | C35: DAMIANE JHON | E35: JENNY C. HUGO | K35: =VLOOKUP(E35,'HEAD OF THE FAMILY'!$B$6:$J1851,9,FALSE) -> BLK 1
A36: =IF(B36="","",ROW()-5) -> 31 | B36: BULOS | C36: DARRISE JUDIEL | E36: JENNY C. HUGO | K36: =VLOOKUP(E36,'HEAD OF THE FAMILY'!$B$6:$J1851,9,FALSE) -> BLK 1
A37: =IF(B37="","",ROW()-5) -> 32 | B37: PARAS | C37: JANICE | E37: DILLON PARAS | K37: =VLOOKUP(E37,'HEAD OF THE FAMILY'!$B$6:$J1851,9,FALSE) -> BLK 1
A38: =IF(B38="","",ROW()-5) -> 33 | B38: PARAS | C38: ESTIAN | E38: DILLON PARAS | K38: =VLOOKUP(E38,'HEAD OF THE FAMILY'!$B$6:$J1851,9,FALSE) -> BLK 1
A39: =IF(B39="","",ROW()-5) -> 34 | B39: CHRISTIAN | C39: JOSON | E39: VIRGILIO JOSON | K39: =VLOOKUP(E39,'HEAD OF THE FAMILY'!$B$6:$J1851,9,FALSE) -> BLK 1
A40: =IF(B40="","",ROW()-5) -> 35 | B40: PARAS | C40: FAITH | E40: MICHELLE PARAS | K40: =VLOOKUP(E40,'HEAD OF THE FAMILY'!$B$6:$J1851,9,FALSE) -> BLK 1
A41: =IF(B41="","",ROW()-5) -> 36 | B41: RAFIÑAN | C41: KING STANLEY | E41: JONATHAN RAFIÑAN | K41: =VLOOKUP(E41,'HEAD OF THE FAMILY'!$B$6:$J1851,9,FALSE) -> BLK 1
A42: =IF(B42="","",ROW()-5) -> 37 | B42: RAFIÑAN | C42: JACK NATHAN | E42: JONATHAN RAFIÑAN | K42: =VLOOKUP(E42,'HEAD OF THE FAMILY'!$B$6:$J1851,9,FALSE) -> BLK 1
...

Sheet OVERVIEWS
L3: PLEASE DONT TOUCH ANYTHING
B4: BARANGAY SAN MIGUEL 2 TOTAL
B5: HEAD OF THE FAMILY: | C5: =COUNT('HEAD OF THE FAMILY'!A6:A1007) -> 819
B6: CHILDREN: | C6: =COUNT(CHILDREN!A6:A1007) -> 1430
B7: SENIOR: | C7: =SUM(D13:E14,D20:E21,D27:E28,D34:E35,I13:J14,I20:J21,I27:J28,I34:J35) -> 232
D8: ACTIVE
B9: BARANGAY SAN MIGUEL 2 TOTAL | D9: REGISTRATION | G9: BARANGAY SAN MIGUEL 2 TOTAL | I9: REGISTRATION
B10: BLOCK: | C10: BLK 1 | D10: HEAD | E10: PARTNER | G10: BLOCK: | H10: BLK 41 | I10: HEAD | J10: PARTNER
B11: HEAD OF THE FAMILY: | C11: =COUNTIF('HEAD OF THE FAMILY'!$J$6:$J1007,C10) -> 69 | D11: =COUNTIFS('HEAD OF THE FAMILY'!$J$6:$J1007,C10,'HEAD OF THE FAMILY'!$F$6:$F1007,$D$8) -> 62 | E11: =COUNTIFS('HEAD OF THE FAMILY'!$J$6:$J1007,C10,'HEAD OF THE FAMILY'!$N$6:$N1007,$D$8) -> 14 | G11: HEAD OF THE FAMILY: | H11: =COUNTIF('HEAD OF THE FAMILY'!$J$6:$J1007,H10) -> 93 | I11: =COUNTIFS('HEAD OF THE FAMILY'!$J$6:$J1007,H10,'HEAD OF THE FAMILY'!$F$6:$F1007,$D$8) -> 82 | J11: =COUNTIFS('HEAD OF THE FAMILY'!$J$6:$J1007,H10,'HEAD OF THE FAMILY'!$N$6:$N1007,$D$8) -> 38
B12: CHILDREN: | C12: =COUNTIF(CHILDREN!$K$6:$K1007,C10) -> 102 | G12: CHILDREN: | H12: =COUNTIF(CHILDREN!$K$6:$K1007,H10) -> 157
C13: SENIOR | D13: =COUNTIFS('HEAD OF THE FAMILY'!$J$6:$J1007,C10,'HEAD OF THE FAMILY'!$C$6:$C1007,C13) -> 19 | E13: =COUNTIFS('HEAD OF THE FAMILY'!$J$6:$J1007,C10,'HEAD OF THE FAMILY'!$I$6:$I1007,C13) -> 4 | H13: SENIOR | I13: =COUNTIFS('HEAD OF THE FAMILY'!$J$6:$J1007,H10,'HEAD OF THE FAMILY'!$C$6:$C1007,H13) -> 25 | J13: =COUNTIFS('HEAD OF THE FAMILY'!$J$6:$J1007,H10,'HEAD OF THE FAMILY'!$I$6:$I1007,H13) -> 6
C14: BRGY. OFFICIALS, SENIOR | D14: =COUNTIFS('HEAD OF THE FAMILY'!$J$6:$J1007,C10,'HEAD OF THE FAMILY'!$C$6:$C1007,C14) -> 0 | E14: =COUNTIFS('HEAD OF THE FAMILY'!$J$6:$J1007,C10,'HEAD OF THE FAMILY'!$I$6:$I1007,C14) -> 0 | H14: BRGY. OFFICIALS, SENIOR | I14: =COUNTIFS('HEAD OF THE FAMILY'!$J$6:$J1007,H10,'HEAD OF THE FAMILY'!$C$6:$C1007,H14) -> 0 | J14: =COUNTIFS('HEAD OF THE FAMILY'!$J$6:$J1007,H10,'HEAD OF THE FAMILY'!$I$6:$I1007,H14) -> 0
B16: BARANGAY SAN MIGUEL 2 TOTAL | D16: REGISTRATION | G16: BARANGAY SAN MIGUEL 2 TOTAL | I16: REGISTRATION
B17: BLOCK: | C17: BLK 45 | D17: HEAD | E17: PARTNER | G17: BLOCK: | H17: BLK 46 | I17: HEAD | J17: PARTNER
B18: HEAD OF THE FAMILY: | C18: =COUNTIF('HEAD OF THE FAMILY'!$J$6:$J1007,C17) -> 113 | D18: =COUNTIFS('HEAD OF THE FAMILY'!$J$6:$J1007,C17,'HEAD OF THE FAMILY'!$F$6:$F1007,$D$8) -> 88 | E18: =COUNTIFS('HEAD OF THE FAMILY'!$J$6:$J1007,C17,'HEAD OF THE FAMILY'!$N$6:$N1007,$D$8) -> 54 | G18: HEAD OF THE FAMILY: | H18: =COUNTIF('HEAD OF THE FAMILY'!$J$6:$J1007,H17) -> 130 | I18: =COUNTIFS('HEAD OF THE FAMILY'!$J$6:$J1007,H17,'HEAD OF THE FAMILY'!$F$6:$F1007,$D$8) -> 107 | J18: =COUNTIFS('HEAD OF THE FAMILY'!$J$6:$J1007,H17,'HEAD OF THE FAMILY'!$N$6:$N1007,$D$8) -> 55
B19: CHILDREN: | C19: =COUNTIF(CHILDREN!$K$6:$K1007,C17) -> 191 | G19: CHILDREN: | H19: =COUNTIF(CHILDREN!$K$6:$K1007,H17) -> 191
C20: SENIOR | D20: =COUNTIFS('HEAD OF THE FAMILY'!$J$6:$J1007,C17,'HEAD OF THE FAMILY'!$C$6:$C1007,C20) -> 29 | E20: =COUNTIFS('HEAD OF THE FAMILY'!$J$6:$J1007,C17,'HEAD OF THE FAMILY'!$I$6:$I1007,C20) -> 10 | H20: SENIOR | I20: =COUNTIFS('HEAD OF THE FAMILY'!$J$6:$J1007,H17,'HEAD OF THE FAMILY'!$C$6:$C1007,H20) -> 27 | J20: =COUNTIFS('HEAD OF THE FAMILY'!$J$6:$J1007,H17,'HEAD OF THE FAMILY'!$I$6:$I1007,H20) -> 5
C21: BRGY. OFFICIALS, SENIOR | D21: =COUNTIFS('HEAD OF THE FAMILY'!$J$6:$J1007,C17,'HEAD OF THE FAMILY'!$C$6:$C1007,C21) -> 2 | E21: =COUNTIFS('HEAD OF THE FAMILY'!$J$6:$J1007,C17,'HEAD OF THE FAMILY'!$I$6:$I1007,C21) -> 0 | H21: BRGY. OFFICIALS, SENIOR | I21: =COUNTIFS('HEAD OF THE FAMILY'!$J$6:$J1007,H17,'HEAD OF THE FAMILY'!$C$6:$C1007,H21) -> 1 | J21: =COUNTIFS('HEAD OF THE FAMILY'!$J$6:$J1007,H17,'HEAD OF THE FAMILY'!$I$6:$I1007,H21) -> 0
B23: BARANGAY SAN MIGUEL 2 TOTAL | D23: REGISTRATION | G23: BARANGAY SAN MIGUEL 2 TOTAL | I23: REGISTRATION
B24: BLOCK: | C24: BLK 3 | D24: HEAD | E24: PARTNER | G24: BLOCK: | H24: BLOCK 4 | I24: HEAD | J24: PARTNER
B25: HEAD OF THE FAMILY: | C25: =COUNTIF('HEAD OF THE FAMILY'!$J$6:$J1007,C24) -> 85 | D25: =COUNTIFS('HEAD OF THE FAMILY'!$J$6:$J1007,C24,'HEAD OF THE FAMILY'!$F$6:$F1007,$D$8) -> 65 | E25: =COUNTIFS('HEAD OF THE FAMILY'!$J$6:$J1007,C24,'HEAD OF THE FAMILY'!$N$6:$N1007,$D$8) -> 37 | G25: HEAD OF THE FAMILY: | H25: =COUNTIF('HEAD OF THE FAMILY'!$J$6:$J1007,H24) -> 133 | I25: =COUNTIFS('HEAD OF THE FAMILY'!$J$6:$J1007,H24,'HEAD OF THE FAMILY'!$F$6:$F1007,$D$8) -> 110 | J25: =COUNTIFS('HEAD OF THE FAMILY'!$J$6:$J1007,H24,'HEAD OF THE FAMILY'!$N$6:$N1007,$D$8) -> 56
B26: CHILDREN: | C26: =COUNTIF(CHILDREN!$K$6:$K1007,C24) -> 154 | G26: CHILDREN: | H26: =COUNTIF(CHILDREN!$K$6:$K1007,H24) -> 242
C27: SENIOR | D27: =COUNTIFS('HEAD OF THE FAMILY'!$J$6:$J1007,C24,'HEAD OF THE FAMILY'!$C$6:$C1007,C27) -> 14 | E27: =COUNTIFS('HEAD OF THE FAMILY'!$J$6:$J1007,C24,'HEAD OF THE FAMILY'!$I$6:$I1007,C27) -> 4 | H27: SENIOR | I27: =COUNTIFS('HEAD OF THE FAMILY'!$J$6:$J1007,H24,'HEAD OF THE FAMILY'!$C$6:$C1007,H27) -> 27 | J27: =COUNTIFS('HEAD OF THE FAMILY'!$J$6:$J1007,H24,'HEAD OF THE FAMILY'!$I$6:$I1007,H27) -> 6
C28: BRGY. OFFICIALS, SENIOR | D28: =COUNTIFS('HEAD OF THE FAMILY'!$J$6:$J1007,C24,'HEAD OF THE FAMILY'!$C$6:$C1007,C28) -> 0 | E28: =COUNTIFS('HEAD OF THE FAMILY'!$J$6:$J1007,C24,'HEAD OF THE FAMILY'!$I$6:$I1007,C28) -> 0 | H28: BRGY. OFFICIALS, SENIOR | I28: =COUNTIFS('HEAD OF THE FAMILY'!$J$6:$J1007,H24,'HEAD OF THE FAMILY'!$C$6:$C1007,H28) -> 1 | J28: =COUNTIFS('HEAD OF THE FAMILY'!$J$6:$J1007,H24,'HEAD OF THE FAMILY'!$I$6:$I1007,H28) -> 2
B30: BARANGAY SAN MIGUEL 2 TOTAL | D30: REGISTRATION | G30: BARANGAY SAN MIGUEL 2 TOTAL | I30: REGISTRATION
B31: BLOCK: | C31: BLK 5 | D31: HEAD | E31: PARTNER | G31: BLOCK: | H31: BLK 49 | I31: HEAD | J31: PARTNER
B32: HEAD OF THE FAMILY: | C32: =COUNTIF('HEAD OF THE FAMILY'!$J$6:$J1007,C31) -> 129 | D32: =COUNTIFS('HEAD OF THE FAMILY'!$J$6:$J1007,C31,'HEAD OF THE FAMILY'!$F$6:$F1007,$D$8) -> 108 | E32: =COUNTIFS('HEAD OF THE FAMILY'!$J$6:$J1007,C31,'HEAD OF THE FAMILY'!$N$6:$N1007,$D$8) -> 49 | G32: HEAD OF THE FAMILY: | H32: =COUNTIF('HEAD OF THE FAMILY'!$J$6:$J1007,H31) -> 66 | I32: =COUNTIFS('HEAD OF THE FAMILY'!$J$6:$J1007,H31,'HEAD OF THE FAMILY'!$F$6:$F1007,$D$8) -> 52 | J32: =COUNTIFS('HEAD OF THE FAMILY'!$J$6:$J1007,H31,'HEAD OF THE FAMILY'!$N$6:$N1007,$D$8) -> 25
B33: CHILDREN: | C33: =COUNTIF(CHILDREN!$K$6:$K1007,C31) -> 224 | G33: CHILDREN: | H33: =COUNTIF(CHILDREN!$K$6:$K1007,H31) -> 118
C34: SENIOR | D34: =COUNTIFS('HEAD OF THE FAMILY'!$J$6:$J1007,C31,'HEAD OF THE FAMILY'!$C$6:$C1007,C34) -> 23 | E34: =COUNTIFS('HEAD OF THE FAMILY'!$J$6:$J1007,C31,'HEAD OF THE FAMILY'!$I$6:$I1007,C34) -> 6 | H34: SENIOR | I34: =COUNTIFS('HEAD OF THE FAMILY'!$J$6:$J1007,H31,'HEAD OF THE FAMILY'!$C$6:$C1007,H34) -> 16 | J34: =COUNTIFS('HEAD OF THE FAMILY'!$J$6:$J1007,H31,'HEAD OF THE FAMILY'!$I$6:$I1007,H34) -> 5
C35: BRGY. OFFICIALS, SENIOR | D35: =COUNTIFS('HEAD OF THE FAMILY'!$J$6:$J1007,C31,'HEAD OF THE FAMILY'!$C$6:$C1007,C35) -> 0 | E35: =COUNTIFS('HEAD OF THE FAMILY'!$J$6:$J1007,C31,'HEAD OF THE FAMILY'!$I$6:$I1007,C35) -> 0 | H35: BRGY. OFFICIALS, SENIOR | I35: =COUNTIFS('HEAD OF THE FAMILY'!$J$6:$J1007,H31,'HEAD OF THE FAMILY'!$C$6:$C1007,H35) -> 0 | J35: =COUNTIFS('HEAD OF THE FAMILY'!$J$6:$J1007,H31,'HEAD OF THE FAMILY'!$I$6:$I1007,H35) -> 0

Sheet CATEGORY FILTER
B2: CATEGORY: | C2: SENIOR | L2: CATEGORY: | M2: BRGY. OFFICIALS
B3: COUNT | C3: =COUNT(A6:A1934) -> 185 | L3: COUNT | M3: =COUNT(K6:K1934) -> 12
A4: HEAD OF THE FAMILY | K4: PARTNER
A5: NO. | B5: NAME | C5: CATEGORY | D5: BLK | K5: NO. | L5: NAME | M5: CATEGORY
A6: =IF(B6="","",ROW()-5) -> 1 | B6: =IFERROR(__xludf.DUMMYFUNCTION("IFERROR(FILTER('HEAD OF THE FAMILY'!B6:C1934,ISNUMBER(SEARCH(LOWER(C2), LOWER('HEAD OF THE FAMILY'!C6:C1934)))), ""NO MATCH FOUND"")"),"ADELAIDA O. PULGA") -> ADELAIDA O. PULGA | C6: =IFERROR(__xludf.DUMMYFUNCTION("""COMPUTED_VALUE"""),"SENIOR") -> SENIOR | D6: =VLOOKUP(B6,'HEAD OF THE FAMILY'!B6:J1934,9,FALSE) -> BLOCK 4 | K6: =IF(L6="","",ROW()-5) -> 1 | L6: =IFERROR(__xludf.DUMMYFUNCTION("IFERROR(FILTER('HEAD OF THE FAMILY'!H6:I1934,ISNUMBER(SEARCH(LOWER(M2), LOWER('HEAD OF THE FAMILY'!I6:I1934)))), ""NO MATCH FOUND"")"),"MARY JOY A CAMPOS") -> MARY JOY A CAMPOS | M6: =IFERROR(__xludf.DUMMYFUNCTION("""COMPUTED_VALUE"""),"BRGY. OFFICIALS") -> BRGY. OFFICIALS
A7: =IF(B7="","",ROW()-5) -> 2 | B7: =IFERROR(__xludf.DUMMYFUNCTION("""COMPUTED_VALUE"""),"ADORACION LLENO") -> ADORACION LLENO | C7: =IFERROR(__xludf.DUMMYFUNCTION("""COMPUTED_VALUE"""),"SENIOR") -> SENIOR | D7: =VLOOKUP(B7,'HEAD OF THE FAMILY'!B7:J1934,9,FALSE) -> BLK 46 | G7: HEAD | H7: PARTNER | I7: TOTAL | K7: =IF(L7="","",ROW()-5) -> 2 | L7: =IFERROR(__xludf.DUMMYFUNCTION("""COMPUTED_VALUE"""),"ELSIE HIPOLITO") -> ELSIE HIPOLITO | M7: =IFERROR(__xludf.DUMMYFUNCTION("""COMPUTED_VALUE"""),"BRGY. OFFICIALS") -> BRGY. OFFICIALS
A8: =IF(B8="","",ROW()-5) -> 3 | B8: =IFERROR(__xludf.DUMMYFUNCTION("""COMPUTED_VALUE"""),"AGAPITO A. HILARIO") -> AGAPITO A. HILARIO | C8: =IFERROR(__xludf.DUMMYFUNCTION("""COMPUTED_VALUE"""),"SENIOR") -> SENIOR | D8: =VLOOKUP(B8,'HEAD OF THE FAMILY'!B8:J1934,9,FALSE) -> BLK 1 | F8: SENIOR: | G8: 179 | H8: 48 | I8: =SUM(G8:H8) -> 227 | K8: =IF(L8="","",ROW()-5) -> 3 | L8: =IFERROR(__xludf.DUMMYFUNCTION("""COMPUTED_VALUE"""),"ROSEMARIE GUTIERREZ") -> ROSEMARIE GUTIERREZ | M8: =IFERROR(__xludf.DUMMYFUNCTION("""COMPUTED_VALUE"""),"BRGY. OFFICIALS") -> BRGY. OFFICIALS
A9: =IF(B9="","",ROW()-5) -> 4 | B9: =IFERROR(__xludf.DUMMYFUNCTION("""COMPUTED_VALUE"""),"AGOSTO ESTILLANA") -> AGOSTO ESTILLANA | C9: =IFERROR(__xludf.DUMMYFUNCTION("""COMPUTED_VALUE"""),"SENIOR") -> SENIOR | D9: =VLOOKUP(B9,'HEAD OF THE FAMILY'!B9:J1934,9,FALSE) -> BLK 41 | F9: PWD | G9: 13 | H9: 12 | I9: =SUM(G9:H9) -> 25 | K9: =IF(L9="","",ROW()-5) -> 4 | L9: =IFERROR(__xludf.DUMMYFUNCTION("""COMPUTED_VALUE"""),"ELBA DOLORES E. QUIJADO") -> ELBA DOLORES E. QUIJADO | M9: =IFERROR(__xludf.DUMMYFUNCTION("""COMPUTED_VALUE"""),"BRGY. OFFICIALS, SENIOR") -> BRGY. OFFICIALS, SENIOR
A10: =IF(B10="","",ROW()-5) -> 5 | B10: =IFERROR(__xludf.DUMMYFUNCTION("""COMPUTED_VALUE"""),"ALBERTO A MACABENTA") -> ALBERTO A MACABENTA | C10: =IFERROR(__xludf.DUMMYFUNCTION("""COMPUTED_VALUE"""),"SENIOR") -> SENIOR | D10: =VLOOKUP(B10,'HEAD OF THE FAMILY'!B10:J1934,9,FALSE) -> BLK 45 | F10: 4PS | G10: 12 | H10: 17 | I10: =SUM(G10:H10) -> 29 | K10: =IF(L10="","",ROW()-5) -> 5 | L10: =IFERROR(__xludf.DUMMYFUNCTION("""COMPUTED_VALUE"""),"LEONORA J. EDRALIN") -> LEONORA J. EDRALIN | M10: =IFERROR(__xludf.DUMMYFUNCTION("""COMPUTED_VALUE"""),"BRGY. OFFICIALS") -> BRGY. OFFICIALS
A11: =IF(B11="","",ROW()-5) -> 6 | B11: =IFERROR(__xludf.DUMMYFUNCTION("""COMPUTED_VALUE"""),"ALBERTO E DE GUZMAN") -> ALBERTO E DE GUZMAN | C11: =IFERROR(__xludf.DUMMYFUNCTION("""COMPUTED_VALUE"""),"SENIOR") -> SENIOR | D11: =VLOOKUP(B11,'HEAD OF THE FAMILY'!B11:J1934,9,FALSE) -> BLK 46 | F11: SOLO PARENT | G11: 12 | H11: 2 | I11: =SUM(G11:H11) -> 14 | K11: =IF(L11="","",ROW()-5) -> 6 | L11: =IFERROR(__xludf.DUMMYFUNCTION("""COMPUTED_VALUE"""),"IRENE JOY JOVEN") -> IRENE JOY JOVEN | M11: =IFERROR(__xludf.DUMMYFUNCTION("""COMPUTED_VALUE"""),"BRGY. OFFICIALS") -> BRGY. OFFICIALS
A12: =IF(B12="","",ROW()-5) -> 7 | B12: =IFERROR(__xludf.DUMMYFUNCTION("""COMPUTED_VALUE"""),"ALBERTO LOBRIO SR.") -> ALBERTO LOBRIO SR. | C12: =IFERROR(__xludf.DUMMYFUNCTION("""COMPUTED_VALUE"""),"SENIOR") -> SENIOR | D12: =VLOOKUP(B12,'HEAD OF THE FAMILY'!B12:J1934,9,FALSE) -> BLK 49 | F12: OFFICIALS | G12: 30 | H12: 12 | I12: =SUM(G12:H12) -> 42 | K12: =IF(L12="","",ROW()-5) -> 7 | L12: =IFERROR(__xludf.DUMMYFUNCTION("""COMPUTED_VALUE"""),"MARY ANN LUCEÑO") -> MARY ANN LUCEÑO | M12: =IFERROR(__xludf.DUMMYFUNCTION("""COMPUTED_VALUE"""),"BRGY. OFFICIALS") -> BRGY. OFFICIALS
A13: =IF(B13="","",ROW()-5) -> 8 | B13: =IFERROR(__xludf.DUMMYFUNCTION("""COMPUTED_VALUE"""),"ALBERTO MANUEL") -> ALBERTO MANUEL | C13: =IFERROR(__xludf.DUMMYFUNCTION("""COMPUTED_VALUE"""),"SENIOR") -> SENIOR | D13: =VLOOKUP(B13,'HEAD OF THE FAMILY'!B13:J1934,9,FALSE) -> BLK 46 | F13: KDBM | G13: 8 | H13: 10 | I13: =SUM(G13:H13) -> 18 | K13: =IF(L13="","",ROW()-5) -> 8 | L13: =IFERROR(__xludf.DUMMYFUNCTION("""COMPUTED_VALUE"""),"MARIBETH MALAIT") -> MARIBETH MALAIT | M13: =IFERROR(__xludf.DUMMYFUNCTION("""COMPUTED_VALUE"""),"BRGY. OFFICIALS") -> BRGY. OFFICIALS
A14: =IF(B14="","",ROW()-5) -> 9 | B14: =IFERROR(__xludf.DUMMYFUNCTION("""COMPUTED_VALUE"""),"ALEXANDER ALONZO") -> ALEXANDER ALONZO | C14: =IFERROR(__xludf.DUMMYFUNCTION("""COMPUTED_VALUE"""),"SENIOR") -> SENIOR | D14: =VLOOKUP(B14,'HEAD OF THE FAMILY'!B14:J1934,9,FALSE) -> BLK 1 | F14: 3RD GEN | G14: 21 | H14: 2 | I14: =SUM(G14:H14) -> 23 | K14: =IF(L14="","",ROW()-5) -> 9 | L14: =IFERROR(__xludf.DUMMYFUNCTION("""COMPUTED_VALUE"""),"BEATRIZ D. EVANGELISTA") -> BEATRIZ D. EVANGELISTA | M14: =IFERROR(__xludf.DUMMYFUNCTION("""COMPUTED_VALUE"""),"BRGY. OFFICIALS") -> BRGY. OFFICIALS
A15: =IF(B15="","",ROW()-5) -> 10 | B15: =IFERROR(__xludf.DUMMYFUNCTION("""COMPUTED_VALUE"""),"ALEXANDER CAMPAÑA") -> ALEXANDER CAMPAÑA | C15: =IFERROR(__xludf.DUMMYFUNCTION("""COMPUTED_VALUE"""),"SENIOR") -> SENIOR | D15: =VLOOKUP(B15,'HEAD OF THE FAMILY'!B15:J1934,9,FALSE) -> BLK 1 | K15: =IF(L15="","",ROW()-5) -> 10 | L15: =IFERROR(__xludf.DUMMYFUNCTION("""COMPUTED_VALUE"""),"JERLYN H. LEBOSADA") -> JERLYN H. LEBOSADA | M15: =IFERROR(__xludf.DUMMYFUNCTION("""COMPUTED_VALUE"""),"BRGY. OFFICIALS") -> BRGY. OFFICIALS
A16: =IF(B16="","",ROW()-5) -> 11 | B16: =IFERROR(__xludf.DUMMYFUNCTION("""COMPUTED_VALUE"""),"ALICIA D. REYES") -> ALICIA D. REYES | C16: =IFERROR(__xludf.DUMMYFUNCTION("""COMPUTED_VALUE"""),"SENIOR") -> SENIOR | D16: =VLOOKUP(B16,'HEAD OF THE FAMILY'!B16:J1934,9,FALSE) -> BLOCK 4 | K16: =IF(L16="","",ROW()-5) -> 11 | L16: =IFERROR(__xludf.DUMMYFUNCTION("""COMPUTED_VALUE"""),"DOLORES R. BUSCAGAN") -> DOLORES R. BUSCAGAN | M16: =IFERROR(__xludf.DUMMYFUNCTION("""COMPUTED_VALUE"""),"BRGY. OFFICIALS, SENIOR") -> BRGY. OFFICIALS, SENIOR
A17: =IF(B17="","",ROW()-5) -> 12 | B17: =IFERROR(__xludf.DUMMYFUNCTION("""COMPUTED_VALUE"""),"ALICIA R. MAGBANUA") -> ALICIA R. MAGBANUA | C17: =IFERROR(__xludf.DUMMYFUNCTION("""COMPUTED_VALUE"""),"SENIOR") -> SENIOR | D17: =VLOOKUP(B17,'HEAD OF THE FAMILY'!B17:J1934,9,FALSE) -> BLK 45 | K17: =IF(L17="","",ROW()-5) -> 12 | L17: =IFERROR(__xludf.DUMMYFUNCTION("""COMPUTED_VALUE"""),"MELINDA M. ARGOTA") -> MELINDA M. ARGOTA | M17: =IFERROR(__xludf.DUMMYFUNCTION("""COMPUTED_VALUE"""),"BRGY. OFFICIALS") -> BRGY. OFFICIALS
A18: =IF(B18="","",ROW()-5) -> 13 | B18: =IFERROR(__xludf.DUMMYFUNCTION("""COMPUTED_VALUE"""),"AMBROSO ALZAGA") -> AMBROSO ALZAGA | C18: =IFERROR(__xludf.DUMMYFUNCTION("""COMPUTED_VALUE"""),"SENIOR") -> SENIOR | D18: =VLOOKUP(B18,'HEAD OF THE FAMILY'!B18:J1934,9,FALSE) -> BLK 1 | K18: =IF(L18="","",ROW()-5)
A19: =IF(B19="","",ROW()-5) -> 14 | B19: =IFERROR(__xludf.DUMMYFUNCTION("""COMPUTED_VALUE"""),"AMPARO L. MARCOS ") -> AMPARO L. MARCOS | C19: =IFERROR(__xludf.DUMMYFUNCTION("""COMPUTED_VALUE"""),"SENIOR") -> SENIOR | D19: =VLOOKUP(B19,'HEAD OF THE FAMILY'!B19:J1934,9,FALSE) -> BLK 45 | K19: =IF(L19="","",ROW()-5)
A20: =IF(B20="","",ROW()-5) -> 15 | B20: =IFERROR(__xludf.DUMMYFUNCTION("""COMPUTED_VALUE"""),"ANATALIA J. RAFIÑAN") -> ANATALIA J. RAFIÑAN | C20: =IFERROR(__xludf.DUMMYFUNCTION("""COMPUTED_VALUE"""),"SENIOR") -> SENIOR | D20: =VLOOKUP(B20,'HEAD OF THE FAMILY'!B20:J1934,9,FALSE) -> BLK 1 | K20: =IF(L20="","",ROW()-5)
A21: =IF(B21="","",ROW()-5) -> 16 | B21: =IFERROR(__xludf.DUMMYFUNCTION("""COMPUTED_VALUE"""),"ANGELITA E. QUIRIT") -> ANGELITA E. QUIRIT | C21: =IFERROR(__xludf.DUMMYFUNCTION("""COMPUTED_VALUE"""),"SENIOR") -> SENIOR | D21: =VLOOKUP(B21,'HEAD OF THE FAMILY'!B21:J1934,9,FALSE) -> BLOCK 4 | K21: =IF(L21="","",ROW()-5)
A22: =IF(B22="","",ROW()-5) -> 17 | B22: =IFERROR(__xludf.DUMMYFUNCTION("""COMPUTED_VALUE"""),"ANNILYN ROBLES") -> ANNILYN ROBLES | C22: =IFERROR(__xludf.DUMMYFUNCTION("""COMPUTED_VALUE"""),"SENIOR") -> SENIOR | D22: =VLOOKUP(B22,'HEAD OF THE FAMILY'!B22:J1934,9,FALSE) -> BLOCK 4 | K22: =IF(L22="","",ROW()-5)
A23: =IF(B23="","",ROW()-5) -> 18 | B23: =IFERROR(__xludf.DUMMYFUNCTION("""COMPUTED_VALUE"""),"ANTONIO CABER") -> ANTONIO CABER | C23: =IFERROR(__xludf.DUMMYFUNCTION("""COMPUTED_VALUE"""),"BRGY. OFFICIALS, SENIOR") -> BRGY. OFFICIALS, SENIOR | D23: =VLOOKUP(B23,'HEAD OF THE FAMILY'!B23:J1934,9,FALSE) -> BLOCK 4 | K23: =IF(L23="","",ROW()-5)
A24: =IF(B24="","",ROW()-5) -> 19 | B24: =IFERROR(__xludf.DUMMYFUNCTION("""COMPUTED_VALUE"""),"ARNALDO QUIÑONES SR.") -> ARNALDO QUIÑONES SR. | C24: =IFERROR(__xludf.DUMMYFUNCTION("""COMPUTED_VALUE"""),"SENIOR") -> SENIOR | D24: =VLOOKUP(B24,'HEAD OF THE FAMILY'!B24:J1934,9,FALSE) -> BLK 41 | K24: =IF(L24="","",ROW()-5)
A25: =IF(B25="","",ROW()-5) -> 20 | B25: =IFERROR(__xludf.DUMMYFUNCTION("""COMPUTED_VALUE"""),"ARNANDO CLAWIN") -> ARNANDO CLAWIN | C25: =IFERROR(__xludf.DUMMYFUNCTION("""COMPUTED_VALUE"""),"SENIOR") -> SENIOR | D25: =VLOOKUP(B25,'HEAD OF THE FAMILY'!B25:J1934,9,FALSE) -> BLK 46 | K25: =IF(L25="","",ROW()-5)
A26: =IF(B26="","",ROW()-5) -> 21 | B26: =IFERROR(__xludf.DUMMYFUNCTION("""COMPUTED_VALUE"""),"ARTURO M DAGAL") -> ARTURO M DAGAL | C26: =IFERROR(__xludf.DUMMYFUNCTION("""COMPUTED_VALUE"""),"SENIOR") -> SENIOR | D26: =VLOOKUP(B26,'HEAD OF THE FAMILY'!B26:J1934,9,FALSE) -> BLK 45 | K26: =IF(L26="","",ROW()-5)
A27: =IF(B27="","",ROW()-5) -> 22 | B27: =IFERROR(__xludf.DUMMYFUNCTION("""COMPUTED_VALUE"""),"AURORA LAZARO") -> AURORA LAZARO | C27: =IFERROR(__xludf.DUMMYFUNCTION("""COMPUTED_VALUE"""),"SENIOR") -> SENIOR | D27: =VLOOKUP(B27,'HEAD OF THE FAMILY'!B27:J1934,9,FALSE) -> BLOCK 4 | K27: =IF(L27="","",ROW()-5)
A28: =IF(B28="","",ROW()-5) -> 23 | B28: =IFERROR(__xludf.DUMMYFUNCTION("""COMPUTED_VALUE"""),"BAMBINO P. PAZ") -> BAMBINO P. PAZ | C28: =IFERROR(__xludf.DUMMYFUNCTION("""COMPUTED_VALUE"""),"SENIOR") -> SENIOR | D28: =VLOOKUP(B28,'HEAD OF THE FAMILY'!B28:J1934,9,FALSE) -> BLOCK 4 | K28: =IF(L28="","",ROW()-5)
A29: =IF(B29="","",ROW()-5) -> 24 | B29: =IFERROR(__xludf.DUMMYFUNCTION("""COMPUTED_VALUE"""),"BERNARD SARMIENTO") -> BERNARD SARMIENTO | C29: =IFERROR(__xludf.DUMMYFUNCTION("""COMPUTED_VALUE"""),"SENIOR") -> SENIOR | D29: =VLOOKUP(B29,'HEAD OF THE FAMILY'!B29:J1934,9,FALSE) -> BLK 45 | K29: =IF(L29="","",ROW()-5)
A30: =IF(B30="","",ROW()-5) -> 25 | B30: =IFERROR(__xludf.DUMMYFUNCTION("""COMPUTED_VALUE"""),"BIENVENIDO C. VITORIA SR. ") -> BIENVENIDO C. VITORIA SR. | C30: =IFERROR(__xludf.DUMMYFUNCTION("""COMPUTED_VALUE"""),"SENIOR") -> SENIOR | D30: =VLOOKUP(B30,'HEAD OF THE FAMILY'!B30:J1934,9,FALSE) -> BLK 45 | K30: =IF(L30="","",ROW()-5)
A31: =IF(B31="","",ROW()-5) -> 26 | B31: =IFERROR(__xludf.DUMMYFUNCTION("""COMPUTED_VALUE"""),"BRANDO MALAIT") -> BRANDO MALAIT | C31: =IFERROR(__xludf.DUMMYFUNCTION("""COMPUTED_VALUE"""),"N/A, SENIOR") -> N/A, SENIOR | D31: =VLOOKUP(B31,'HEAD OF THE FAMILY'!B31:J1934,9,FALSE) -> BLK 5 | K31: =IF(L31="","",ROW()-5)
A32: =IF(B32="","",ROW()-5) -> 27 | B32: =IFERROR(__xludf.DUMMYFUNCTION("""COMPUTED_VALUE"""),"BRUNO TUCO") -> BRUNO TUCO | C32: =IFERROR(__xludf.DUMMYFUNCTION("""COMPUTED_VALUE"""),"SENIOR") -> SENIOR | D32: =VLOOKUP(B32,'HEAD OF THE FAMILY'!B32:J1934,9,FALSE) -> BLK 45 | K32: =IF(L32="","",ROW()-5)
A33: =IF(B33="","",ROW()-5) -> 28 | B33: =IFERROR(__xludf.DUMMYFUNCTION("""COMPUTED_VALUE"""),"CARMELITA MAAGNO") -> CARMELITA MAAGNO | C33: =IFERROR(__xludf.DUMMYFUNCTION("""COMPUTED_VALUE"""),"SENIOR") -> SENIOR | D33: =VLOOKUP(B33,'HEAD OF THE FAMILY'!B33:J1934,9,FALSE) -> BLK 5 | K33: =IF(L33="","",ROW()-5)
A34: =IF(B34="","",ROW()-5) -> 29 | B34: =IFERROR(__xludf.DUMMYFUNCTION("""COMPUTED_VALUE"""),"CARMELO G. DE GUZMAN") -> CARMELO G. DE GUZMAN | C34: =IFERROR(__xludf.DUMMYFUNCTION("""COMPUTED_VALUE"""),"SENIOR") -> SENIOR | D34: =VLOOKUP(B34,'HEAD OF THE FAMILY'!B34:J1934,9,FALSE) -> BLK 41 | K34: =IF(L34="","",ROW()-5)
A35: =IF(B35="","",ROW()-5) -> 30 | B35: =IFERROR(__xludf.DUMMYFUNCTION("""COMPUTED_VALUE"""),"CAROL DEL ROSARIO") -> CAROL DEL ROSARIO | C35: =IFERROR(__xludf.DUMMYFUNCTION("""COMPUTED_VALUE"""),"SENIOR") -> SENIOR | D35: =VLOOKUP(B35,'HEAD OF THE FAMILY'!B35:J1934,9,FALSE) -> BLK 49 | K35: =IF(L35="","",ROW()-5)
A36: =IF(B36="","",ROW()-5) -> 31 | B36: =IFERROR(__xludf.DUMMYFUNCTION("""COMPUTED_VALUE"""),"CAROLINA TALASTAS") -> CAROLINA TALASTAS | C36: =IFERROR(__xludf.DUMMYFUNCTION("""COMPUTED_VALUE"""),"SENIOR") -> SENIOR | D36: =VLOOKUP(B36,'HEAD OF THE FAMILY'!B36:J1934,9,FALSE) -> BLK 5 | K36: =IF(L36="","",ROW()-5)
A37: =IF(B37="","",ROW()-5) -> 32 | B37: =IFERROR(__xludf.DUMMYFUNCTION("""COMPUTED_VALUE"""),"CELERINA SAÑEZ") -> CELERINA SAÑEZ | C37: =IFERROR(__xludf.DUMMYFUNCTION("""COMPUTED_VALUE"""),"SENIOR") -> SENIOR | D37: =VLOOKUP(B37,'HEAD OF THE FAMILY'!B37:J1934,9,FALSE) -> BLK 3 | K37: =IF(L37="","",ROW()-5)
A38: =IF(B38="","",ROW()-5) -> 33 | B38: =IFERROR(__xludf.DUMMYFUNCTION("""COMPUTED_VALUE"""),"CELSO OREJANA") -> CELSO OREJANA | C38: =IFERROR(__xludf.DUMMYFUNCTION("""COMPUTED_VALUE"""),"SENIOR") -> SENIOR | D38: =VLOOKUP(B38,'HEAD OF THE FAMILY'!B38:J1934,9,FALSE) -> BLK 41 | K38: =IF(L38="","",ROW()-5)
A39: =IF(B39="","",ROW()-5) -> 34 | B39: =IFERROR(__xludf.DUMMYFUNCTION("""COMPUTED_VALUE"""),"CESAR GALLARDO") -> CESAR GALLARDO | C39: =IFERROR(__xludf.DUMMYFUNCTION("""COMPUTED_VALUE"""),"BRGY. OFFICIALS, SENIOR") -> BRGY. OFFICIALS, SENIOR | D39: =VLOOKUP(B39,'HEAD OF THE FAMILY'!B39:J1934,9,FALSE) -> BLK 46 | K39: =IF(L39="","",ROW()-5)
A40: =IF(B40="","",ROW()-5) -> 35 | B40: =IFERROR(__xludf.DUMMYFUNCTION("""COMPUTED_VALUE"""),"CESAR P. PUNZZALAN") -> CESAR P. PUNZZALAN | C40: =IFERROR(__xludf.DUMMYFUNCTION("""COMPUTED_VALUE"""),"SENIOR") -> SENIOR | D40: =VLOOKUP(B40,'HEAD OF THE FAMILY'!B40:J1934,9,FALSE) -> BLK 45 | K40: =IF(L40="","",ROW()-5)
A41: =IF(B41="","",ROW()-5) -> 36 | B41: =IFERROR(__xludf.DUMMYFUNCTION("""COMPUTED_VALUE"""),"CONCEPCION ALONZO") -> CONCEPCION ALONZO | C41: =IFERROR(__xludf.DUMMYFUNCTION("""COMPUTED_VALUE"""),"SENIOR") -> SENIOR | D41: =VLOOKUP(B41,'HEAD OF THE FAMILY'!B41:J1934,9,FALSE) -> BLK 41 | K41: =IF(L41="","",ROW()-5)
...

Sheet SEARCH PROTOTYPE
B2: BARANGAY SAN MIGUEL II DATA INFORMATION
B4: HEAD OF THE FAMILY: | C4: AARON CARL EJANDRA | E4: PARTNER: | F4: =VLOOKUP($C$4,'HEAD OF THE FAMILY'!$B$6:$P1004,7,FALSE) -> MA. LOUELLA L. EJANDRA
B5: CATEGORY: | C5: =VLOOKUP($C$4,'HEAD OF THE FAMILY'!$B$6:$P1004,2,FALSE) -> N/A | E5: CATEGORY: | F5: =VLOOKUP($C$4,'HEAD OF THE FAMILY'!$B$6:$P1004,8,FALSE)
B6: BIRTHDAY: | C6: =VLOOKUP($C$4,'HEAD OF THE FAMILY'!$B$6:$P1004,3,FALSE) | E6: BIRTHDAY: | F6: =VLOOKUP($C$4,'HEAD OF THE FAMILY'!$B$6:$P1004,11,FALSE)
B7: PRECINT NO.: | C7: =VLOOKUP($C$4,'HEAD OF THE FAMILY'!$B$6:$P1004,4,FALSE) | E7: PRECINT NO.: | F7: =VLOOKUP($C$4,'HEAD OF THE FAMILY'!$B$6:$P1004,12,FALSE)
B8: STATUS: | C8: =VLOOKUP($C$4,'HEAD OF THE FAMILY'!$B$6:$P1004,5,FALSE) -> ACTIVE | E8: STATUS: | F8: =VLOOKUP($C$4,'HEAD OF THE FAMILY'!$B$6:$P1004,13,FALSE) -> UNREGISTERED
B9: CHILDREN FOUND: | C9: =COUNT(A15:A1004) -> 3
B10: ADDRESS:
B11: BLK: | C11: =VLOOKUP($C$4,'HEAD OF THE FAMILY'!$B$6:$P1004,9,FALSE) -> BLK 3
B12: LOT: | C12: =VLOOKUP($C$4,'HEAD OF THE FAMILY'!$B$6:$P1004,10,FALSE) -> 5
A14: NO. | B14: =IFERROR(__xludf.DUMMYFUNCTION("QUERY(CHILDREN,""SELECT B,C,F,G,H,I where E='""&C4&""'"",1)"),"SURNAME") -> SURNAME | C14: =IFERROR(__xludf.DUMMYFUNCTION("""COMPUTED_VALUE"""),"FIRSTNAME") -> FIRSTNAME | D14: =IFERROR(__xludf.DUMMYFUNCTION("""COMPUTED_VALUE"""),"CATEGORY") -> CATEGORY | E14: =IFERROR(__xludf.DUMMYFUNCTION("""COMPUTED_VALUE"""),"BIRTHDAY") -> BIRTHDAY | F14: =IFERROR(__xludf.DUMMYFUNCTION("""COMPUTED_VALUE"""),"PRECINT NO.") -> PRECINT NO. | G14: =IFERROR(__xludf.DUMMYFUNCTION("""COMPUTED_VALUE"""),"STATUS") -> STATUS
A15: =IF(B15="","",ROW()-14) -> 1 | B15: =IFERROR(__xludf.DUMMYFUNCTION("""COMPUTED_VALUE"""),"EJANDRA") -> EJANDRA | C15: =IFERROR(__xludf.DUMMYFUNCTION("""COMPUTED_VALUE"""),"RACE ANDREI") -> RACE ANDREI
A16: =IF(B16="","",ROW()-14) -> 2 | B16: =IFERROR(__xludf.DUMMYFUNCTION("""COMPUTED_VALUE"""),"EJANDRA") -> EJANDRA | C16: =IFERROR(__xludf.DUMMYFUNCTION("""COMPUTED_VALUE"""),"RAJE OSHTON") -> RAJE OSHTON
A17: =IF(B17="","",ROW()-14) -> 3 | B17: =IFERROR(__xludf.DUMMYFUNCTION("""COMPUTED_VALUE"""),"EJANDRA") -> EJANDRA | C17: =IFERROR(__xludf.DUMMYFUNCTION("""COMPUTED_VALUE"""),"REIN MAXINE") -> REIN MAXINE
A18: =IF(B18="","",ROW()-14)
A19: =IF(B19="","",ROW()-14)
A20: =IF(B20="","",ROW()-14)
A21: =IF(B21="","",ROW()-14)
A22: =IF(B22="","",ROW()-14)
A23: =IF(B23="","",ROW()-14)
A24: =IF(B24="","",ROW()-14)
A25: =IF(B25="","",ROW()-14)
A26: =IF(B26="","",ROW()-14)
A27: =IF(B27="","",ROW()-14)
A28: =IF(B28="","",ROW()-14)
A29: =IF(B29="","",ROW()-14)
... A1004: =IF(B1004="","",ROW()-14)

Sheet CHILDREN PER BLOCK
B2: FIRSNAME🔎 :
B3: DATA FOUND: | C3: =SUBTOTAL(2,A6:A1501) -> 994
A6: NO. | B6: SURNAME | C6: FIRSTNAME | D6: M.I | E6: HEAD OF THE FAMILY
A7: =IF(B7="","",ROW()-6) -> 1 | B7: =IFERROR(__xludf.DUMMYFUNCTION("IFERROR(FILTER(CHILDREN!B6:I1501,ISNUMBER(SEARCH(LOWER(C2), LOWER(CHILDREN!B6:B1501)))), ""NO MATCH FOUND"")"),"BILLONES") -> BILLONES | C7: =IFERROR(__xludf.DUMMYFUNCTION("""COMPUTED_VALUE"""),"NELJOHN") -> NELJOHN | E7: =IFERROR(__xludf.DUMMYFUNCTION("""COMPUTED_VALUE"""),"NELVIN BILLONES") -> NELVIN BILLONES
A8: =IF(B8="","",ROW()-6) -> 2 | B8: =IFERROR(__xludf.DUMMYFUNCTION("""COMPUTED_VALUE"""),"BILLONES") -> BILLONES | C8: =IFERROR(__xludf.DUMMYFUNCTION("""COMPUTED_VALUE"""),"PRECIUS YHANA") -> PRECIUS YHANA | E8: =IFERROR(__xludf.DUMMYFUNCTION("""COMPUTED_VALUE"""),"NELVIN BILLONES") -> NELVIN BILLONES
A9: =IF(B9="","",ROW()-6) -> 3 | B9: =IFERROR(__xludf.DUMMYFUNCTION("""COMPUTED_VALUE"""),"BILLONES") -> BILLONES | C9: =IFERROR(__xludf.DUMMYFUNCTION("""COMPUTED_VALUE"""),"PRINCE YUAN") -> PRINCE YUAN | E9: =IFERROR(__xludf.DUMMYFUNCTION("""COMPUTED_VALUE"""),"NELVIN BILLONES") -> NELVIN BILLONES
A10: =IF(B10="","",ROW()-6) -> 4 | B10: =IFERROR(__xludf.DUMMYFUNCTION("""COMPUTED_VALUE"""),"BILLONES") -> BILLONES | C10: =IFERROR(__xludf.DUMMYFUNCTION("""COMPUTED_VALUE"""),"NERISSA") -> NERISSA | D10: =IFERROR(__xludf.DUMMYFUNCTION("""COMPUTED_VALUE"""),"P.") -> P. | E10: =IFERROR(__xludf.DUMMYFUNCTION("""COMPUTED_VALUE"""),"NELVIN BILLONES") -> NELVIN BILLONES
A11: =IF(B11="","",ROW()-6) -> 5 | B11: =IFERROR(__xludf.DUMMYFUNCTION("""COMPUTED_VALUE"""),"BILLONES") -> BILLONES | C11: =IFERROR(__xludf.DUMMYFUNCTION("""COMPUTED_VALUE"""),"MARK GIL AERON") -> MARK GIL AERON | D11: =IFERROR(__xludf.DUMMYFUNCTION("""COMPUTED_VALUE"""),"P.") -> P. | E11: =IFERROR(__xludf.DUMMYFUNCTION("""COMPUTED_VALUE"""),"ROGELIO S. BILLONES") -> ROGELIO S. BILLONES
A12: =IF(B12="","",ROW()-6) -> 6 | B12: =IFERROR(__xludf.DUMMYFUNCTION("""COMPUTED_VALUE"""),"MARTIN ") -> MARTIN | C12: =IFERROR(__xludf.DUMMYFUNCTION("""COMPUTED_VALUE"""),"MARIANNE MILES") -> MARIANNE MILES | E12: =IFERROR(__xludf.DUMMYFUNCTION("""COMPUTED_VALUE"""),"NORMAN BILLONES") -> NORMAN BILLONES
A13: =IF(B13="","",ROW()-6) -> 7 | B13: =IFERROR(__xludf.DUMMYFUNCTION("""COMPUTED_VALUE"""),"BILLONES") -> BILLONES | C13: =IFERROR(__xludf.DUMMYFUNCTION("""COMPUTED_VALUE"""),"JOHN VILLMAR") -> JOHN VILLMAR | D13: =IFERROR(__xludf.DUMMYFUNCTION("""COMPUTED_VALUE"""),"M.") -> M. | E13: =IFERROR(__xludf.DUMMYFUNCTION("""COMPUTED_VALUE"""),"NORMAN BILLONES") -> NORMAN BILLONES
A14: =IF(B14="","",ROW()-6) -> 8 | B14: =IFERROR(__xludf.DUMMYFUNCTION("""COMPUTED_VALUE"""),"BILLONES") -> BILLONES | C14: =IFERROR(__xludf.DUMMYFUNCTION("""COMPUTED_VALUE"""),"SHARESCA MILES") -> SHARESCA MILES | D14: =IFERROR(__xludf.DUMMYFUNCTION("""COMPUTED_VALUE"""),"M.") -> M. | E14: =IFERROR(__xludf.DUMMYFUNCTION("""COMPUTED_VALUE"""),"NORMAN BILLONES") -> NORMAN BILLONES
A15: =IF(B15="","",ROW()-6) -> 9 | B15: =IFERROR(__xludf.DUMMYFUNCTION("""COMPUTED_VALUE"""),"BILLONES") -> BILLONES | C15: =IFERROR(__xludf.DUMMYFUNCTION("""COMPUTED_VALUE"""),"AYRA NAINE") -> AYRA NAINE | D15: =IFERROR(__xludf.DUMMYFUNCTION("""COMPUTED_VALUE"""),"M.") -> M. | E15: =IFERROR(__xludf.DUMMYFUNCTION("""COMPUTED_VALUE"""),"NORMAN BILLONES") -> NORMAN BILLONES
A16: =IF(B16="","",ROW()-6) -> 10 | B16: =IFERROR(__xludf.DUMMYFUNCTION("""COMPUTED_VALUE"""),"BILLONES") -> BILLONES | C16: =IFERROR(__xludf.DUMMYFUNCTION("""COMPUTED_VALUE"""),"STEPHEN GAEL") -> STEPHEN GAEL | D16: =IFERROR(__xludf.DUMMYFUNCTION("""COMPUTED_VALUE"""),"M.") -> M. | E16: =IFERROR(__xludf.DUMMYFUNCTION("""COMPUTED_VALUE"""),"NORMAN BILLONES") -> NORMAN BILLONES
A17: =IF(B17="","",ROW()-6) -> 11 | B17: =IFERROR(__xludf.DUMMYFUNCTION("""COMPUTED_VALUE"""),"BILLONES") -> BILLONES | C17: =IFERROR(__xludf.DUMMYFUNCTION("""COMPUTED_VALUE"""),"E.R") -> E.R | E17: =IFERROR(__xludf.DUMMYFUNCTION("""COMPUTED_VALUE"""),"NORMAN BILLONES") -> NORMAN BILLONES
A18: =IF(B18="","",ROW()-6) -> 12 | B18: =IFERROR(__xludf.DUMMYFUNCTION("""COMPUTED_VALUE"""),"LABUTIN ") -> LABUTIN | C18: =IFERROR(__xludf.DUMMYFUNCTION("""COMPUTED_VALUE"""),"JHONROGELIO") -> JHONROGELIO | D18: =IFERROR(__xludf.DUMMYFUNCTION("""COMPUTED_VALUE"""),"B.") -> B. | E18: =IFERROR(__xludf.DUMMYFUNCTION("""COMPUTED_VALUE"""),"ROGELIO A. LABUTIN") -> ROGELIO A. LABUTIN
A19: =IF(B19="","",ROW()-6) -> 13 | B19: =IFERROR(__xludf.DUMMYFUNCTION("""COMPUTED_VALUE"""),"LABUTIN ") -> LABUTIN | C19: =IFERROR(__xludf.DUMMYFUNCTION("""COMPUTED_VALUE"""),"ARZEL") -> ARZEL | D19: =IFERROR(__xludf.DUMMYFUNCTION("""COMPUTED_VALUE"""),"B.") -> B. | E19: =IFERROR(__xludf.DUMMYFUNCTION("""COMPUTED_VALUE"""),"ROGELIO A. LABUTIN") -> ROGELIO A. LABUTIN
A20: =IF(B20="","",ROW()-6) -> 14 | B20: =IFERROR(__xludf.DUMMYFUNCTION("""COMPUTED_VALUE"""),"AYUDAN") -> AYUDAN | C20: =IFERROR(__xludf.DUMMYFUNCTION("""COMPUTED_VALUE"""),"MARIA PAULIN") -> MARIA PAULIN | D20: =IFERROR(__xludf.DUMMYFUNCTION("""COMPUTED_VALUE"""),"C.") -> C. | E20: =IFERROR(__xludf.DUMMYFUNCTION("""COMPUTED_VALUE"""),"RENATO AYUDAN") -> RENATO AYUDAN
A21: =IF(B21="","",ROW()-6) -> 15 | B21: =IFERROR(__xludf.DUMMYFUNCTION("""COMPUTED_VALUE"""),"LAOLA") -> LAOLA | C21: =IFERROR(__xludf.DUMMYFUNCTION("""COMPUTED_VALUE"""),"ELLA") -> ELLA | D21: =IFERROR(__xludf.DUMMYFUNCTION("""COMPUTED_VALUE"""),"C.") -> C. | E21: =IFERROR(__xludf.DUMMYFUNCTION("""COMPUTED_VALUE"""),"RENATO AYUDAN") -> RENATO AYUDAN
A22: =IF(B22="","",ROW()-6) -> 16 | B22: =IFERROR(__xludf.DUMMYFUNCTION("""COMPUTED_VALUE"""),"SALAMAT") -> SALAMAT | C22: =IFERROR(__xludf.DUMMYFUNCTION("""COMPUTED_VALUE"""),"SHAWN JAYVE") -> SHAWN JAYVE | E22: =IFERROR(__xludf.DUMMYFUNCTION("""COMPUTED_VALUE"""),"SHERWIN JAY SALAMAT") -> SHERWIN JAY SALAMAT
A23: =IF(B23="","",ROW()-6) -> 17 | B23: =IFERROR(__xludf.DUMMYFUNCTION("""COMPUTED_VALUE"""),"SALAMAT") -> SALAMAT | C23: =IFERROR(__xludf.DUMMYFUNCTION("""COMPUTED_VALUE"""),"SHAMARA JHADE") -> SHAMARA JHADE | E23: =IFERROR(__xludf.DUMMYFUNCTION("""COMPUTED_VALUE"""),"SHERWIN JAY SALAMAT") -> SHERWIN JAY SALAMAT
A24: =IF(B24="","",ROW()-6) -> 18 | B24: =IFERROR(__xludf.DUMMYFUNCTION("""COMPUTED_VALUE"""),"MIRASOL") -> MIRASOL | C24: =IFERROR(__xludf.DUMMYFUNCTION("""COMPUTED_VALUE"""),"JEFFREY S. MIRASOL") -> JEFFREY S. MIRASOL
A25: =IF(B25="","",ROW()-6) -> 19 | B25: =IFERROR(__xludf.DUMMYFUNCTION("""COMPUTED_VALUE"""),"BADAGUAS") -> BADAGUAS | C25: =IFERROR(__xludf.DUMMYFUNCTION("""COMPUTED_VALUE"""),"JASMIR ALI") -> JASMIR ALI | D25: =IFERROR(__xludf.DUMMYFUNCTION("""COMPUTED_VALUE"""),"M.") -> M. | E25: =IFERROR(__xludf.DUMMYFUNCTION("""COMPUTED_VALUE"""),"JENNALYN S. MIRASOL") -> JENNALYN S. MIRASOL
A26: =IF(B26="","",ROW()-6) -> 20 | B26: =IFERROR(__xludf.DUMMYFUNCTION("""COMPUTED_VALUE"""),"LEBOSADA") -> LEBOSADA | C26: =IFERROR(__xludf.DUMMYFUNCTION("""COMPUTED_VALUE"""),"JANEGELLE") -> JANEGELLE | D26: =IFERROR(__xludf.DUMMYFUNCTION("""COMPUTED_VALUE"""),"H.") -> H. | E26: =IFERROR(__xludf.DUMMYFUNCTION("""COMPUTED_VALUE"""),"AGAPITO A. HILARIO") -> AGAPITO A. HILARIO
A27: =IF(B27="","",ROW()-6) -> 21 | B27: =IFERROR(__xludf.DUMMYFUNCTION("""COMPUTED_VALUE"""),"CABRERA") -> CABRERA | C27: =IFERROR(__xludf.DUMMYFUNCTION("""COMPUTED_VALUE"""),"JAYCEERYN") -> JAYCEERYN | D27: =IFERROR(__xludf.DUMMYFUNCTION("""COMPUTED_VALUE"""),"H.") -> H. | E27: =IFERROR(__xludf.DUMMYFUNCTION("""COMPUTED_VALUE"""),"AGAPITO A. HILARIO") -> AGAPITO A. HILARIO
A28: =IF(B28="","",ROW()-6) -> 22 | B28: =IFERROR(__xludf.DUMMYFUNCTION("""COMPUTED_VALUE"""),"AMASA") -> AMASA | C28: =IFERROR(__xludf.DUMMYFUNCTION("""COMPUTED_VALUE"""),"PRIMO KIEL") -> PRIMO KIEL | E28: =IFERROR(__xludf.DUMMYFUNCTION("""COMPUTED_VALUE"""),"PRINCE NHIMWELL L. AMASA") -> PRINCE NHIMWELL L. AMASA
A29: =IF(B29="","",ROW()-6) -> 23 | B29: =IFERROR(__xludf.DUMMYFUNCTION("""COMPUTED_VALUE"""),"AMASA") -> AMASA | C29: =IFERROR(__xludf.DUMMYFUNCTION("""COMPUTED_VALUE"""),"PRINCE NHIMWELL ") -> PRINCE NHIMWELL | D29: =IFERROR(__xludf.DUMMYFUNCTION("""COMPUTED_VALUE"""),"L.") -> L. | E29: =IFERROR(__xludf.DUMMYFUNCTION("""COMPUTED_VALUE"""),"NHOEL D. AMASA") -> NHOEL D. AMASA
A30: =IF(B30="","",ROW()-6) -> 24 | B30: =IFERROR(__xludf.DUMMYFUNCTION("""COMPUTED_VALUE"""),"AMASA") -> AMASA | C30: =IFERROR(__xludf.DUMMYFUNCTION("""COMPUTED_VALUE"""),"NHICOLE") -> NHICOLE | D30: =IFERROR(__xludf.DUMMYFUNCTION("""COMPUTED_VALUE"""),"L.") -> L. | E30: =IFERROR(__xludf.DUMMYFUNCTION("""COMPUTED_VALUE"""),"NHOEL D. AMASA") -> NHOEL D. AMASA
A31: =IF(B31="","",ROW()-6) -> 25 | B31: =IFERROR(__xludf.DUMMYFUNCTION("""COMPUTED_VALUE"""),"AMASA") -> AMASA | C31: =IFERROR(__xludf.DUMMYFUNCTION("""COMPUTED_VALUE"""),"NHATALEE") -> NHATALEE | D31: =IFERROR(__xludf.DUMMYFUNCTION("""COMPUTED_VALUE"""),"L.") -> L. | E31: =IFERROR(__xludf.DUMMYFUNCTION("""COMPUTED_VALUE"""),"NHOEL D. AMASA") -> NHOEL D. AMASA
A32: =IF(B32="","",ROW()-6) -> 26 | B32: =IFERROR(__xludf.DUMMYFUNCTION("""COMPUTED_VALUE"""),"AMASA") -> AMASA | C32: =IFERROR(__xludf.DUMMYFUNCTION("""COMPUTED_VALUE"""),"ANGELITO") -> ANGELITO | D32: =IFERROR(__xludf.DUMMYFUNCTION("""COMPUTED_VALUE"""),"L.") -> L. | E32: =IFERROR(__xludf.DUMMYFUNCTION("""COMPUTED_VALUE"""),"NHOEL D. AMASA") -> NHOEL D. AMASA
A33: =IF(B33="","",ROW()-6) -> 27 | B33: =IFERROR(__xludf.DUMMYFUNCTION("""COMPUTED_VALUE"""),"AMASA") -> AMASA | C33: =IFERROR(__xludf.DUMMYFUNCTION("""COMPUTED_VALUE"""),"ROY") -> ROY | E33: =IFERROR(__xludf.DUMMYFUNCTION("""COMPUTED_VALUE"""),"NELSON D. AMASA") -> NELSON D. AMASA
A34: =IF(B34="","",ROW()-6) -> 28 | B34: =IFERROR(__xludf.DUMMYFUNCTION("""COMPUTED_VALUE"""),"AMASA ") -> AMASA | C34: =IFERROR(__xludf.DUMMYFUNCTION("""COMPUTED_VALUE"""),"JOSEPH") -> JOSEPH | D34: =IFERROR(__xludf.DUMMYFUNCTION("""COMPUTED_VALUE"""),"I.") -> I. | E34: =IFERROR(__xludf.DUMMYFUNCTION("""COMPUTED_VALUE"""),"JOSHUA D. AMASA") -> JOSHUA D. AMASA
A35: =IF(B35="","",ROW()-6) -> 29 | B35: =IFERROR(__xludf.DUMMYFUNCTION("""COMPUTED_VALUE"""),"BULOS") -> BULOS | C35: =IFERROR(__xludf.DUMMYFUNCTION("""COMPUTED_VALUE"""),"DAPHNE CHLOE") -> DAPHNE CHLOE | E35: =IFERROR(__xludf.DUMMYFUNCTION("""COMPUTED_VALUE"""),"JENNY C. HUGO") -> JENNY C. HUGO
A36: =IF(B36="","",ROW()-6) -> 30 | B36: =IFERROR(__xludf.DUMMYFUNCTION("""COMPUTED_VALUE"""),"BULOS") -> BULOS | C36: =IFERROR(__xludf.DUMMYFUNCTION("""COMPUTED_VALUE"""),"DAMIANE JHON") -> DAMIANE JHON | E36: =IFERROR(__xludf.DUMMYFUNCTION("""COMPUTED_VALUE"""),"JENNY C. HUGO") -> JENNY C. HUGO
A37: =IF(B37="","",ROW()-6) -> 31 | B37: =IFERROR(__xludf.DUMMYFUNCTION("""COMPUTED_VALUE"""),"BULOS") -> BULOS | C37: =IFERROR(__xludf.DUMMYFUNCTION("""COMPUTED_VALUE"""),"DARRISE JUDIEL") -> DARRISE JUDIEL | E37: =IFERROR(__xludf.DUMMYFUNCTION("""COMPUTED_VALUE"""),"JENNY C. HUGO") -> JENNY C. HUGO
A38: =IF(B38="","",ROW()-6) -> 32 | B38: =IFERROR(__xludf.DUMMYFUNCTION("""COMPUTED_VALUE"""),"PARAS") -> PARAS | C38: =IFERROR(__xludf.DUMMYFUNCTION("""COMPUTED_VALUE"""),"JANICE") -> JANICE | E38: =IFERROR(__xludf.DUMMYFUNCTION("""COMPUTED_VALUE"""),"DILLON PARAS") -> DILLON PARAS
A39: =IF(B39="","",ROW()-6) -> 33 | B39: =IFERROR(__xludf.DUMMYFUNCTION("""COMPUTED_VALUE"""),"PARAS") -> PARAS | C39: =IFERROR(__xludf.DUMMYFUNCTION("""COMPUTED_VALUE"""),"ESTIAN") -> ESTIAN | E39: =IFERROR(__xludf.DUMMYFUNCTION("""COMPUTED_VALUE"""),"DILLON PARAS") -> DILLON PARAS
A40: =IF(B40="","",ROW()-6) -> 34 | B40: =IFERROR(__xludf.DUMMYFUNCTION("""COMPUTED_VALUE"""),"CHRISTIAN") -> CHRISTIAN | C40: =IFERROR(__xludf.DUMMYFUNCTION("""COMPUTED_VALUE"""),"JOSON") -> JOSON | E40: =IFERROR(__xludf.DUMMYFUNCTION("""COMPUTED_VALUE"""),"VIRGILIO JOSON") -> VIRGILIO JOSON
A41: =IF(B41="","",ROW()-6) -> 35 | B41: =IFERROR(__xludf.DUMMYFUNCTION("""COMPUTED_VALUE"""),"PARAS") -> PARAS | C41: =IFERROR(__xludf.DUMMYFUNCTION("""COMPUTED_VALUE"""),"FAITH") -> FAITH | E41: =IFERROR(__xludf.DUMMYFUNCTION("""COMPUTED_VALUE"""),"MICHELLE PARAS") -> MICHELLE PARAS
A42: =IF(B42="","",ROW()-6) -> 36 | B42: =IFERROR(__xludf.DUMMYFUNCTION("""COMPUTED_VALUE"""),"RAFIÑAN") -> RAFIÑAN | C42: =IFERROR(__xludf.DUMMYFUNCTION("""COMPUTED_VALUE"""),"KING STANLEY") -> KING STANLEY | E42: =IFERROR(__xludf.DUMMYFUNCTION("""COMPUTED_VALUE"""),"JONATHAN RAFIÑAN") -> JONATHAN RAFIÑAN
A43: =IF(B43="","",ROW()-6) -> 37 | B43: =IFERROR(__xludf.DUMMYFUNCTION("""COMPUTED_VALUE"""),"RAFIÑAN") -> RAFIÑAN | C43: =IFERROR(__xludf.DUMMYFUNCTION("""COMPUTED_VALUE"""),"JACK NATHAN ") -> JACK NATHAN | E43: =IFERROR(__xludf.DUMMYFUNCTION("""COMPUTED_VALUE"""),"JONATHAN RAFIÑAN") -> JONATHAN RAFIÑAN
...

Sheet PH OR R
B3: PH = PAMASKONG HANDOG | J3: PH = PAMASKONG HANDOG
B4: R = RICE | J4: R = RICE
B5: SEARCH: | C5: N/A | J5: SEARCH: | K5: R
C6: =COUNT(A10:A1942) -> 61
A8: COUNT | B8: HEAD OF THE FAMILY | D8: ADDRESS | F8: VOTER REGISTRATION | I8: COUNT | J8: PARTNER | L8: ADDRESS | N8: VOTER REGISTRATION
A9: NO. | B9: =IFERROR(__xludf.DUMMYFUNCTION("QUERY(HEADOFTHEFAM,""SELECT B,C,J,K,F where G='""&C5&""'"",1)"),"FIRST NAME / MI. / LAST NAME") -> FIRST NAME / MI. / LAST NAME | C9: =IFERROR(__xludf.DUMMYFUNCTION("""COMPUTED_VALUE"""),"CATEGORY") -> CATEGORY | D9: =IFERROR(__xludf.DUMMYFUNCTION("""COMPUTED_VALUE"""),"BLK") -> BLK | E9: =IFERROR(__xludf.DUMMYFUNCTION("""COMPUTED_VALUE"""),"LOT") -> LOT | F9: =IFERROR(__xludf.DUMMYFUNCTION("""COMPUTED_VALUE"""),"STATUS") -> STATUS | I9: NO. | J9: =IFERROR(__xludf.DUMMYFUNCTION("QUERY(HEADOFTHEFAM,""SELECT H,I,J,K,F where O='""&K5&""'"",1)"),"FIRST NAME / MI. / LAST NAME") -> FIRST NAME / MI. / LAST NAME | K9: =IFERROR(__xludf.DUMMYFUNCTION("""COMPUTED_VALUE"""),"CATEGORY") -> CATEGORY | L9: =IFERROR(__xludf.DUMMYFUNCTION("""COMPUTED_VALUE"""),"BLK") -> BLK | M9: =IFERROR(__xludf.DUMMYFUNCTION("""COMPUTED_VALUE"""),"LOT") -> LOT | N9: =IFERROR(__xludf.DUMMYFUNCTION("""COMPUTED_VALUE"""),"STATUS") -> STATUS
A10: =IF(B10="","",ROW()-9) -> 1 | B10: =IFERROR(__xludf.DUMMYFUNCTION("""COMPUTED_VALUE"""),"ALEX CHENG") -> ALEX CHENG | C10: =IFERROR(__xludf.DUMMYFUNCTION("""COMPUTED_VALUE"""),"THIRD GEN") -> THIRD GEN | D10: =IFERROR(__xludf.DUMMYFUNCTION("""COMPUTED_VALUE"""),"BLOCK 4") -> BLOCK 4 | E10: =IFERROR(__xludf.DUMMYFUNCTION("""COMPUTED_VALUE"""),37.0) -> 37 | F10: =IFERROR(__xludf.DUMMYFUNCTION("""COMPUTED_VALUE"""),"INACTIVE") -> INACTIVE | I10: =IF(J10="","",ROW()-9)
A11: =IF(B11="","",ROW()-9) -> 2 | B11: =IFERROR(__xludf.DUMMYFUNCTION("""COMPUTED_VALUE"""),"ALICIA R. MAGBANUA") -> ALICIA R. MAGBANUA | C11: =IFERROR(__xludf.DUMMYFUNCTION("""COMPUTED_VALUE"""),"SENIOR") -> SENIOR | D11: =IFERROR(__xludf.DUMMYFUNCTION("""COMPUTED_VALUE"""),"BLK 45") -> BLK 45 | E11: =IFERROR(__xludf.DUMMYFUNCTION("""COMPUTED_VALUE"""),26.0) -> 26 | F11: =IFERROR(__xludf.DUMMYFUNCTION("""COMPUTED_VALUE"""),"INACTIVE") -> INACTIVE | I11: =IF(J11="","",ROW()-9)
A12: =IF(B12="","",ROW()-9) -> 3 | B12: =IFERROR(__xludf.DUMMYFUNCTION("""COMPUTED_VALUE"""),"ANJO A CRISTOBAL") -> ANJO A CRISTOBAL | C12: =IFERROR(__xludf.DUMMYFUNCTION("""COMPUTED_VALUE"""),"N/A") -> N/A | D12: =IFERROR(__xludf.DUMMYFUNCTION("""COMPUTED_VALUE"""),"BLK 46") -> BLK 46 | E12: =IFERROR(__xludf.DUMMYFUNCTION("""COMPUTED_VALUE"""),15.0) -> 15 | F12: =IFERROR(__xludf.DUMMYFUNCTION("""COMPUTED_VALUE"""),"UNREGISTERED") -> UNREGISTERED | I12: =IF(J12="","",ROW()-9)
A13: =IF(B13="","",ROW()-9) -> 4 | B13: =IFERROR(__xludf.DUMMYFUNCTION("""COMPUTED_VALUE"""),"ANNA LIZA DE GUZMAN") -> ANNA LIZA DE GUZMAN | C13: =IFERROR(__xludf.DUMMYFUNCTION("""COMPUTED_VALUE"""),"N/A") -> N/A | D13: =IFERROR(__xludf.DUMMYFUNCTION("""COMPUTED_VALUE"""),"BLK 3") -> BLK 3 | E13: =IFERROR(__xludf.DUMMYFUNCTION("""COMPUTED_VALUE"""),13.0) -> 13 | F13: =IFERROR(__xludf.DUMMYFUNCTION("""COMPUTED_VALUE"""),"UNREGISTERED") -> UNREGISTERED | I13: =IF(J13="","",ROW()-9)
A14: =IF(B14="","",ROW()-9) -> 5 | B14: =IFERROR(__xludf.DUMMYFUNCTION("""COMPUTED_VALUE"""),"ANTHONY EUGENIO") -> ANTHONY EUGENIO | C14: =IFERROR(__xludf.DUMMYFUNCTION("""COMPUTED_VALUE"""),"N/A") -> N/A | D14: =IFERROR(__xludf.DUMMYFUNCTION("""COMPUTED_VALUE"""),"BLK 46") -> BLK 46 | E14: =IFERROR(__xludf.DUMMYFUNCTION("""COMPUTED_VALUE"""),36.0) -> 36 | F14: =IFERROR(__xludf.DUMMYFUNCTION("""COMPUTED_VALUE"""),"UNREGISTERED") -> UNREGISTERED | I14: =IF(J14="","",ROW()-9)
A15: =IF(B15="","",ROW()-9) -> 6 | B15: =IFERROR(__xludf.DUMMYFUNCTION("""COMPUTED_VALUE"""),"ARNULFO DAVID") -> ARNULFO DAVID | C15: =IFERROR(__xludf.DUMMYFUNCTION("""COMPUTED_VALUE"""),"N/A") -> N/A | D15: =IFERROR(__xludf.DUMMYFUNCTION("""COMPUTED_VALUE"""),"BLK 3") -> BLK 3 | E15: =IFERROR(__xludf.DUMMYFUNCTION("""COMPUTED_VALUE"""),26.0) -> 26 | F15: =IFERROR(__xludf.DUMMYFUNCTION("""COMPUTED_VALUE"""),"UNREGISTERED") -> UNREGISTERED | I15: =IF(J15="","",ROW()-9)
A16: =IF(B16="","",ROW()-9) -> 7 | B16: =IFERROR(__xludf.DUMMYFUNCTION("""COMPUTED_VALUE"""),"AROB CHRISTOPHER S. AVILES") -> AROB CHRISTOPHER S. AVILES | C16: =IFERROR(__xludf.DUMMYFUNCTION("""COMPUTED_VALUE"""),"N/A") -> N/A | D16: =IFERROR(__xludf.DUMMYFUNCTION("""COMPUTED_VALUE"""),"BLK 3") -> BLK 3 | E16: =IFERROR(__xludf.DUMMYFUNCTION("""COMPUTED_VALUE"""),10.0) -> 10 | F16: =IFERROR(__xludf.DUMMYFUNCTION("""COMPUTED_VALUE"""),"INACTIVE") -> INACTIVE | I16: =IF(J16="","",ROW()-9)
A17: =IF(B17="","",ROW()-9) -> 8 | B17: =IFERROR(__xludf.DUMMYFUNCTION("""COMPUTED_VALUE"""),"ARWILL FULONG") -> ARWILL FULONG | C17: =IFERROR(__xludf.DUMMYFUNCTION("""COMPUTED_VALUE"""),"N/A") -> N/A | D17: =IFERROR(__xludf.DUMMYFUNCTION("""COMPUTED_VALUE"""),"BLK 46") -> BLK 46 | E17: =IFERROR(__xludf.DUMMYFUNCTION("""COMPUTED_VALUE"""),8.0) -> 8 | F17: =IFERROR(__xludf.DUMMYFUNCTION("""COMPUTED_VALUE"""),"UNREGISTERED") -> UNREGISTERED | I17: =IF(J17="","",ROW()-9)
A18: =IF(B18="","",ROW()-9) -> 9 | B18: =IFERROR(__xludf.DUMMYFUNCTION("""COMPUTED_VALUE"""),"BERNARDO N. LONTOC") -> BERNARDO N. LONTOC | C18: =IFERROR(__xludf.DUMMYFUNCTION("""COMPUTED_VALUE"""),"N/A") -> N/A | D18: =IFERROR(__xludf.DUMMYFUNCTION("""COMPUTED_VALUE"""),"BLK 5") -> BLK 5 | E18: =IFERROR(__xludf.DUMMYFUNCTION("""COMPUTED_VALUE"""),22.0) -> 22 | F18: =IFERROR(__xludf.DUMMYFUNCTION("""COMPUTED_VALUE"""),"UNREGISTERED") -> UNREGISTERED | H18: N/A | I18: 77 | J18: 77
A19: =IF(B19="","",ROW()-9) -> 10 | B19: =IFERROR(__xludf.DUMMYFUNCTION("""COMPUTED_VALUE"""),"CAROL D. REYES") -> CAROL D. REYES | C19: =IFERROR(__xludf.DUMMYFUNCTION("""COMPUTED_VALUE"""),"N/A") -> N/A | D19: =IFERROR(__xludf.DUMMYFUNCTION("""COMPUTED_VALUE"""),"BLOCK 4") -> BLOCK 4 | E19: =IFERROR(__xludf.DUMMYFUNCTION("""COMPUTED_VALUE"""),8.0) -> 8 | F19: =IFERROR(__xludf.DUMMYFUNCTION("""COMPUTED_VALUE"""),"UNREGISTERED") -> UNREGISTERED | H19: R | I19: 377 | J19: 370
A20: =IF(B20="","",ROW()-9) -> 11 | B20: =IFERROR(__xludf.DUMMYFUNCTION("""COMPUTED_VALUE"""),"CHERRYLYN GALLARDO") -> CHERRYLYN GALLARDO | C20: =IFERROR(__xludf.DUMMYFUNCTION("""COMPUTED_VALUE"""),"N/A") -> N/A | D20: =IFERROR(__xludf.DUMMYFUNCTION("""COMPUTED_VALUE"""),"BLK 46") -> BLK 46 | F20: =IFERROR(__xludf.DUMMYFUNCTION("""COMPUTED_VALUE"""),"UNREGISTERED") -> UNREGISTERED | H20: PH | I20: 258 | J20: 272
A21: =IF(B21="","",ROW()-9) -> 12 | B21: =IFERROR(__xludf.DUMMYFUNCTION("""COMPUTED_VALUE"""),"DAISY GUTIERREZ") -> DAISY GUTIERREZ | C21: =IFERROR(__xludf.DUMMYFUNCTION("""COMPUTED_VALUE"""),"N/A") -> N/A | D21: =IFERROR(__xludf.DUMMYFUNCTION("""COMPUTED_VALUE"""),"BLK 45") -> BLK 45 | E21: =IFERROR(__xludf.DUMMYFUNCTION("""COMPUTED_VALUE"""),14.0) -> 14 | F21: =IFERROR(__xludf.DUMMYFUNCTION("""COMPUTED_VALUE"""),"INACTIVE") -> INACTIVE | I21: =SUM(I19:I20) -> 635 | J21: =SUM(J18:J20) -> 719
A22: =IF(B22="","",ROW()-9) -> 13 | B22: =IFERROR(__xludf.DUMMYFUNCTION("""COMPUTED_VALUE"""),"DOMINGO DESDIR") -> DOMINGO DESDIR | C22: =IFERROR(__xludf.DUMMYFUNCTION("""COMPUTED_VALUE"""),"N/A") -> N/A | D22: =IFERROR(__xludf.DUMMYFUNCTION("""COMPUTED_VALUE"""),"BLK 45") -> BLK 45 | E22: =IFERROR(__xludf.DUMMYFUNCTION("""COMPUTED_VALUE"""),2.0) -> 2 | F22: =IFERROR(__xludf.DUMMYFUNCTION("""COMPUTED_VALUE"""),"INACTIVE") -> INACTIVE | I22: =IF(J22="","",ROW()-9)
A23: =IF(B23="","",ROW()-9) -> 14 | B23: =IFERROR(__xludf.DUMMYFUNCTION("""COMPUTED_VALUE"""),"DOMINGO LOBRIO") -> DOMINGO LOBRIO | C23: =IFERROR(__xludf.DUMMYFUNCTION("""COMPUTED_VALUE"""),"N/A") -> N/A | D23: =IFERROR(__xludf.DUMMYFUNCTION("""COMPUTED_VALUE"""),"BLK 49") -> BLK 49 | E23: =IFERROR(__xludf.DUMMYFUNCTION("""COMPUTED_VALUE"""),27.0) -> 27 | F23: =IFERROR(__xludf.DUMMYFUNCTION("""COMPUTED_VALUE"""),"UNREGISTERED") -> UNREGISTERED | I23: =IF(J23="","",ROW()-9)
A24: =IF(B24="","",ROW()-9) -> 15 | B24: =IFERROR(__xludf.DUMMYFUNCTION("""COMPUTED_VALUE"""),"DOMINIC SORILLA") -> DOMINIC SORILLA | C24: =IFERROR(__xludf.DUMMYFUNCTION("""COMPUTED_VALUE"""),"N/A") -> N/A | D24: =IFERROR(__xludf.DUMMYFUNCTION("""COMPUTED_VALUE"""),"BLK 5") -> BLK 5 | E24: =IFERROR(__xludf.DUMMYFUNCTION("""COMPUTED_VALUE"""),9.0) -> 9 | F24: =IFERROR(__xludf.DUMMYFUNCTION("""COMPUTED_VALUE"""),"UNREGISTERED") -> UNREGISTERED | I24: =IF(J24="","",ROW()-9)
A25: =IF(B25="","",ROW()-9) -> 16 | B25: =IFERROR(__xludf.DUMMYFUNCTION("""COMPUTED_VALUE"""),"EFREN B. GAMBAN") -> EFREN B. GAMBAN | C25: =IFERROR(__xludf.DUMMYFUNCTION("""COMPUTED_VALUE"""),"N/A") -> N/A | D25: =IFERROR(__xludf.DUMMYFUNCTION("""COMPUTED_VALUE"""),"BLK 3") -> BLK 3 | E25: =IFERROR(__xludf.DUMMYFUNCTION("""COMPUTED_VALUE"""),27.0) -> 27 | F25: =IFERROR(__xludf.DUMMYFUNCTION("""COMPUTED_VALUE"""),"UNREGISTERED") -> UNREGISTERED | I25: =IF(J25="","",ROW()-9)
A26: =IF(B26="","",ROW()-9) -> 17 | B26: =IFERROR(__xludf.DUMMYFUNCTION("""COMPUTED_VALUE"""),"ERLINDA NIEGAS") -> ERLINDA NIEGAS | C26: =IFERROR(__xludf.DUMMYFUNCTION("""COMPUTED_VALUE"""),"N/A") -> N/A | D26: =IFERROR(__xludf.DUMMYFUNCTION("""COMPUTED_VALUE"""),"BLK 3") -> BLK 3 | E26: =IFERROR(__xludf.DUMMYFUNCTION("""COMPUTED_VALUE"""),26.0) -> 26 | F26: =IFERROR(__xludf.DUMMYFUNCTION("""COMPUTED_VALUE"""),"ACTIVE") -> ACTIVE | I26: =IF(J26="","",ROW()-9)
